22/06/23 (02:38:34) | ERROR: Exception while getting cpu frequency!
22/06/23 (02:38:34) | ERROR: [Errno 2] No such file or directory (originated from sysctl(HW_CPU_FREQ))
Traceback (most recent call last):
  File "/opt/homebrew/bin/bpytop", line 3080, in _collect
    if CONFIG.show_cpu_freq and hasattr(psutil.cpu_freq(), "current"):
                                        ^^^^^^^^^^^^^^^^^
  File "/opt/homebrew/Cellar/bpytop/1.0.68/libexec/lib/python3.11/site-packages/psutil/__init__.py", line 1864, in cpu_freq
    ret = _psplatform.cpu_freq()
          ^^^^^^^^^^^^^^^^^^^^^^
  File "/opt/homebrew/Cellar/bpytop/1.0.68/libexec/lib/python3.11/site-packages/psutil/_psosx.py", line 179, in cpu_freq
    curr, min_, max_ = cext.cpu_freq()
                       ^^^^^^^^^^^^^^^
FileNotFoundError: [Errno 2] No such file or directory (originated from sysctl(HW_CPU_FREQ))
22/06/23 (02:40:14) | ERROR: Exception while getting cpu frequency!
22/06/23 (02:40:14) | ERROR: [Errno 2] No such file or directory (originated from sysctl(HW_CPU_FREQ))
Traceback (most recent call last):
  File "/opt/homebrew/bin/bpytop", line 3080, in _collect
    if CONFIG.show_cpu_freq and hasattr(psutil.cpu_freq(), "current"):
                                        ^^^^^^^^^^^^^^^^^
  File "/opt/homebrew/Cellar/bpytop/1.0.68/libexec/lib/python3.11/site-packages/psutil/__init__.py", line 1864, in cpu_freq
    ret = _psplatform.cpu_freq()
          ^^^^^^^^^^^^^^^^^^^^^^
  File "/opt/homebrew/Cellar/bpytop/1.0.68/libexec/lib/python3.11/site-packages/psutil/_psosx.py", line 179, in cpu_freq
    curr, min_, max_ = cext.cpu_freq()
                       ^^^^^^^^^^^^^^^
FileNotFoundError: [Errno 2] No such file or directory (originated from sysctl(HW_CPU_FREQ))
22/06/23 (02:40:33) | ERROR: Exception while getting cpu frequency!
22/06/23 (02:40:33) | ERROR: [Errno 2] No such file or directory (originated from sysctl(HW_CPU_FREQ))
Traceback (most recent call last):
  File "/opt/homebrew/bin/bpytop", line 3080, in _collect
    if CONFIG.show_cpu_freq and hasattr(psutil.cpu_freq(), "current"):
                                        ^^^^^^^^^^^^^^^^^
  File "/opt/homebrew/Cellar/bpytop/1.0.68/libexec/lib/python3.11/site-packages/psutil/__init__.py", line 1864, in cpu_freq
    ret = _psplatform.cpu_freq()
          ^^^^^^^^^^^^^^^^^^^^^^
  File "/opt/homebrew/Cellar/bpytop/1.0.68/libexec/lib/python3.11/site-packages/psutil/_psosx.py", line 179, in cpu_freq
    curr, min_, max_ = cext.cpu_freq()
                       ^^^^^^^^^^^^^^^
FileNotFoundError: [Errno 2] No such file or directory (originated from sysctl(HW_CPU_FREQ))
22/06/23 (02:42:34) | ERROR: Exception while getting cpu frequency!
22/06/23 (02:42:34) | ERROR: [Errno 2] No such file or directory (originated from sysctl(HW_CPU_FREQ))
Traceback (most recent call last):
  File "/opt/homebrew/bin/bpytop", line 3080, in _collect
    if CONFIG.show_cpu_freq and hasattr(psutil.cpu_freq(), "current"):
                                        ^^^^^^^^^^^^^^^^^
  File "/opt/homebrew/Cellar/bpytop/1.0.68/libexec/lib/python3.11/site-packages/psutil/__init__.py", line 1864, in cpu_freq
    ret = _psplatform.cpu_freq()
          ^^^^^^^^^^^^^^^^^^^^^^
  File "/opt/homebrew/Cellar/bpytop/1.0.68/libexec/lib/python3.11/site-packages/psutil/_psosx.py", line 179, in cpu_freq
    curr, min_, max_ = cext.cpu_freq()
                       ^^^^^^^^^^^^^^^
FileNotFoundError: [Errno 2] No such file or directory (originated from sysctl(HW_CPU_FREQ))
22/06/23 (02:44:45) | ERROR: Exception while getting cpu frequency!
22/06/23 (02:44:45) | ERROR: [Errno 2] No such file or directory (originated from sysctl(HW_CPU_FREQ))
Traceback (most recent call last):
  File "/opt/homebrew/bin/bpytop", line 3080, in _collect
    if CONFIG.show_cpu_freq and hasattr(psutil.cpu_freq(), "current"):
                                        ^^^^^^^^^^^^^^^^^
  File "/opt/homebrew/Cellar/bpytop/1.0.68/libexec/lib/python3.11/site-packages/psutil/__init__.py", line 1864, in cpu_freq
    ret = _psplatform.cpu_freq()
          ^^^^^^^^^^^^^^^^^^^^^^
  File "/opt/homebrew/Cellar/bpytop/1.0.68/libexec/lib/python3.11/site-packages/psutil/_psosx.py", line 179, in cpu_freq
    curr, min_, max_ = cext.cpu_freq()
                       ^^^^^^^^^^^^^^^
FileNotFoundError: [Errno 2] No such file or directory (originated from sysctl(HW_CPU_FREQ))
22/06/23 (02:46:23) | ERROR: Exception while getting cpu frequency!
22/06/23 (02:46:23) | ERROR: [Errno 2] No such file or directory (originated from sysctl(HW_CPU_FREQ))
Traceback (most recent call last):
  File "/opt/homebrew/bin/bpytop", line 3080, in _collect
    if CONFIG.show_cpu_freq and hasattr(psutil.cpu_freq(), "current"):
                                        ^^^^^^^^^^^^^^^^^
  File "/opt/homebrew/Cellar/bpytop/1.0.68/libexec/lib/python3.11/site-packages/psutil/__init__.py", line 1864, in cpu_freq
    ret = _psplatform.cpu_freq()
          ^^^^^^^^^^^^^^^^^^^^^^
  File "/opt/homebrew/Cellar/bpytop/1.0.68/libexec/lib/python3.11/site-packages/psutil/_psosx.py", line 179, in cpu_freq
    curr, min_, max_ = cext.cpu_freq()
                       ^^^^^^^^^^^^^^^
FileNotFoundError: [Errno 2] No such file or directory (originated from sysctl(HW_CPU_FREQ))
22/06/23 (02:59:12) | ERROR: Exception while getting cpu frequency!
22/06/23 (02:59:12) | ERROR: [Errno 2] No such file or directory (originated from sysctl(HW_CPU_FREQ))
Traceback (most recent call last):
  File "/opt/homebrew/bin/bpytop", line 3080, in _collect
    if CONFIG.show_cpu_freq and hasattr(psutil.cpu_freq(), "current"):
                                        ^^^^^^^^^^^^^^^^^
  File "/opt/homebrew/Cellar/bpytop/1.0.68/libexec/lib/python3.11/site-packages/psutil/__init__.py", line 1864, in cpu_freq
    ret = _psplatform.cpu_freq()
          ^^^^^^^^^^^^^^^^^^^^^^
  File "/opt/homebrew/Cellar/bpytop/1.0.68/libexec/lib/python3.11/site-packages/psutil/_psosx.py", line 179, in cpu_freq
    curr, min_, max_ = cext.cpu_freq()
                       ^^^^^^^^^^^^^^^
FileNotFoundError: [Errno 2] No such file or directory (originated from sysctl(HW_CPU_FREQ))
22/06/23 (13:01:54) | ERROR: Exception while getting cpu frequency!
22/06/23 (13:01:54) | ERROR: [Errno 2] No such file or directory (originated from sysctl(HW_CPU_FREQ))
Traceback (most recent call last):
  File "/opt/homebrew/bin/bpytop", line 3080, in _collect
    if CONFIG.show_cpu_freq and hasattr(psutil.cpu_freq(), "current"):
                                        ^^^^^^^^^^^^^^^^^
  File "/opt/homebrew/Cellar/bpytop/1.0.68/libexec/lib/python3.11/site-packages/psutil/__init__.py", line 1864, in cpu_freq
    ret = _psplatform.cpu_freq()
          ^^^^^^^^^^^^^^^^^^^^^^
  File "/opt/homebrew/Cellar/bpytop/1.0.68/libexec/lib/python3.11/site-packages/psutil/_psosx.py", line 179, in cpu_freq
    curr, min_, max_ = cext.cpu_freq()
                       ^^^^^^^^^^^^^^^
FileNotFoundError: [Errno 2] No such file or directory (originated from sysctl(HW_CPU_FREQ))
22/06/23 (13:10:41) | ERROR: Exception while getting cpu frequency!
22/06/23 (13:10:41) | ERROR: [Errno 2] No such file or directory (originated from sysctl(HW_CPU_FREQ))
Traceback (most recent call last):
  File "/opt/homebrew/bin/bpytop", line 3080, in _collect
    if CONFIG.show_cpu_freq and hasattr(psutil.cpu_freq(), "current"):
                                        ^^^^^^^^^^^^^^^^^
  File "/opt/homebrew/Cellar/bpytop/1.0.68/libexec/lib/python3.11/site-packages/psutil/__init__.py", line 1864, in cpu_freq
    ret = _psplatform.cpu_freq()
          ^^^^^^^^^^^^^^^^^^^^^^
  File "/opt/homebrew/Cellar/bpytop/1.0.68/libexec/lib/python3.11/site-packages/psutil/_psosx.py", line 179, in cpu_freq
    curr, min_, max_ = cext.cpu_freq()
                       ^^^^^^^^^^^^^^^
FileNotFoundError: [Errno 2] No such file or directory (originated from sysctl(HW_CPU_FREQ))
22/06/23 (15:39:34) | ERROR: Exception while getting cpu frequency!
22/06/23 (15:39:34) | ERROR: [Errno 2] No such file or directory (originated from sysctl(HW_CPU_FREQ))
Traceback (most recent call last):
  File "/opt/homebrew/bin/bpytop", line 3080, in _collect
    if CONFIG.show_cpu_freq and hasattr(psutil.cpu_freq(), "current"):
                                        ^^^^^^^^^^^^^^^^^
  File "/opt/homebrew/Cellar/bpytop/1.0.68/libexec/lib/python3.11/site-packages/psutil/__init__.py", line 1864, in cpu_freq
    ret = _psplatform.cpu_freq()
          ^^^^^^^^^^^^^^^^^^^^^^
  File "/opt/homebrew/Cellar/bpytop/1.0.68/libexec/lib/python3.11/site-packages/psutil/_psosx.py", line 179, in cpu_freq
    curr, min_, max_ = cext.cpu_freq()
                       ^^^^^^^^^^^^^^^
FileNotFoundError: [Errno 2] No such file or directory (originated from sysctl(HW_CPU_FREQ))
22/06/23 (15:52:26) | ERROR: Exception while getting cpu frequency!
22/06/23 (15:52:26) | ERROR: [Errno 2] No such file or directory (originated from sysctl(HW_CPU_FREQ))
Traceback (most recent call last):
  File "/opt/homebrew/bin/bpytop", line 3080, in _collect
    if CONFIG.show_cpu_freq and hasattr(psutil.cpu_freq(), "current"):
                                        ^^^^^^^^^^^^^^^^^
  File "/opt/homebrew/Cellar/bpytop/1.0.68/libexec/lib/python3.11/site-packages/psutil/__init__.py", line 1864, in cpu_freq
    ret = _psplatform.cpu_freq()
          ^^^^^^^^^^^^^^^^^^^^^^
  File "/opt/homebrew/Cellar/bpytop/1.0.68/libexec/lib/python3.11/site-packages/psutil/_psosx.py", line 179, in cpu_freq
    curr, min_, max_ = cext.cpu_freq()
                       ^^^^^^^^^^^^^^^
FileNotFoundError: [Errno 2] No such file or directory (originated from sysctl(HW_CPU_FREQ))
22/06/23 (15:52:26) | ERROR: <urlopen error [SSL: CERTIFICATE_VERIFY_FAILED] certificate verify failed: unable to get local issuer certificate (_ssl.c:1002)>
Traceback (most recent call last):
  File "/opt/homebrew/Cellar/python@3.11/3.11.4/Frameworks/Python.framework/Versions/3.11/lib/python3.11/urllib/request.py", line 1348, in do_open
    h.request(req.get_method(), req.selector, req.data, headers,
  File "/opt/homebrew/Cellar/python@3.11/3.11.4/Frameworks/Python.framework/Versions/3.11/lib/python3.11/http/client.py", line 1286, in request
    self._send_request(method, url, body, headers, encode_chunked)
  File "/opt/homebrew/Cellar/python@3.11/3.11.4/Frameworks/Python.framework/Versions/3.11/lib/python3.11/http/client.py", line 1332, in _send_request
    self.endheaders(body, encode_chunked=encode_chunked)
  File "/opt/homebrew/Cellar/python@3.11/3.11.4/Frameworks/Python.framework/Versions/3.11/lib/python3.11/http/client.py", line 1281, in endheaders
    self._send_output(message_body, encode_chunked=encode_chunked)
  File "/opt/homebrew/Cellar/python@3.11/3.11.4/Frameworks/Python.framework/Versions/3.11/lib/python3.11/http/client.py", line 1041, in _send_output
    self.send(msg)
  File "/opt/homebrew/Cellar/python@3.11/3.11.4/Frameworks/Python.framework/Versions/3.11/lib/python3.11/http/client.py", line 979, in send
    self.connect()
  File "/opt/homebrew/Cellar/python@3.11/3.11.4/Frameworks/Python.framework/Versions/3.11/lib/python3.11/http/client.py", line 1458, in connect
    self.sock = self._context.wrap_socket(self.sock,
                ^^^^^^^^^^^^^^^^^^^^^^^^^^^^^^^^^^^^
  File "/opt/homebrew/Cellar/python@3.11/3.11.4/Frameworks/Python.framework/Versions/3.11/lib/python3.11/ssl.py", line 517, in wrap_socket
    return self.sslsocket_class._create(
           ^^^^^^^^^^^^^^^^^^^^^^^^^^^^^
  File "/opt/homebrew/Cellar/python@3.11/3.11.4/Frameworks/Python.framework/Versions/3.11/lib/python3.11/ssl.py", line 1075, in _create
    self.do_handshake()
  File "/opt/homebrew/Cellar/python@3.11/3.11.4/Frameworks/Python.framework/Versions/3.11/lib/python3.11/ssl.py", line 1346, in do_handshake
    self._sslobj.do_handshake()
ssl.SSLCertVerificationError: [SSL: CERTIFICATE_VERIFY_FAILED] certificate verify failed: unable to get local issuer certificate (_ssl.c:1002)

During handling of the above exception, another exception occurred:

Traceback (most recent call last):
  File "/opt/homebrew/bin/bpytop", line 5029, in _checker
    with urllib.request.urlopen("https://github.com/aristocratos/bpytop/raw/master/bpytop.py", timeout=5) as source: # type: ignore
         ^^^^^^^^^^^^^^^^^^^^^^^^^^^^^^^^^^^^^^^^^^^^^^^^^^^^^^^^^^^^^^^^^^^^^^^^^^^^^^^^^^^^^^^^^^^^^^^^
  File "/opt/homebrew/Cellar/python@3.11/3.11.4/Frameworks/Python.framework/Versions/3.11/lib/python3.11/urllib/request.py", line 216, in urlopen
    return opener.open(url, data, timeout)
           ^^^^^^^^^^^^^^^^^^^^^^^^^^^^^^^
  File "/opt/homebrew/Cellar/python@3.11/3.11.4/Frameworks/Python.framework/Versions/3.11/lib/python3.11/urllib/request.py", line 519, in open
    response = self._open(req, data)
               ^^^^^^^^^^^^^^^^^^^^^
  File "/opt/homebrew/Cellar/python@3.11/3.11.4/Frameworks/Python.framework/Versions/3.11/lib/python3.11/urllib/request.py", line 536, in _open
    result = self._call_chain(self.handle_open, protocol, protocol +
             ^^^^^^^^^^^^^^^^^^^^^^^^^^^^^^^^^^^^^^^^^^^^^^^^^^^^^^^
  File "/opt/homebrew/Cellar/python@3.11/3.11.4/Frameworks/Python.framework/Versions/3.11/lib/python3.11/urllib/request.py", line 496, in _call_chain
    result = func(*args)
             ^^^^^^^^^^^
  File "/opt/homebrew/Cellar/python@3.11/3.11.4/Frameworks/Python.framework/Versions/3.11/lib/python3.11/urllib/request.py", line 1391, in https_open
    return self.do_open(http.client.HTTPSConnection, req,
           ^^^^^^^^^^^^^^^^^^^^^^^^^^^^^^^^^^^^^^^^^^^^^^
  File "/opt/homebrew/Cellar/python@3.11/3.11.4/Frameworks/Python.framework/Versions/3.11/lib/python3.11/urllib/request.py", line 1351, in do_open
    raise URLError(err)
urllib.error.URLError: <urlopen error [SSL: CERTIFICATE_VERIFY_FAILED] certificate verify failed: unable to get local issuer certificate (_ssl.c:1002)>
23/06/23 (14:13:54) | ERROR: Exception while getting cpu frequency!
23/06/23 (14:13:54) | ERROR: [Errno 2] No such file or directory (originated from sysctl(HW_CPU_FREQ))
Traceback (most recent call last):
  File "/opt/homebrew/bin/bpytop", line 3080, in _collect
    if CONFIG.show_cpu_freq and hasattr(psutil.cpu_freq(), "current"):
                                        ^^^^^^^^^^^^^^^^^
  File "/opt/homebrew/Cellar/bpytop/1.0.68/libexec/lib/python3.11/site-packages/psutil/__init__.py", line 1864, in cpu_freq
    ret = _psplatform.cpu_freq()
          ^^^^^^^^^^^^^^^^^^^^^^
  File "/opt/homebrew/Cellar/bpytop/1.0.68/libexec/lib/python3.11/site-packages/psutil/_psosx.py", line 179, in cpu_freq
    curr, min_, max_ = cext.cpu_freq()
                       ^^^^^^^^^^^^^^^
FileNotFoundError: [Errno 2] No such file or directory (originated from sysctl(HW_CPU_FREQ))
23/06/23 (14:13:54) | ERROR: <urlopen error [SSL: CERTIFICATE_VERIFY_FAILED] certificate verify failed: unable to get local issuer certificate (_ssl.c:1002)>
Traceback (most recent call last):
  File "/opt/homebrew/Cellar/python@3.11/3.11.4/Frameworks/Python.framework/Versions/3.11/lib/python3.11/urllib/request.py", line 1348, in do_open
    h.request(req.get_method(), req.selector, req.data, headers,
  File "/opt/homebrew/Cellar/python@3.11/3.11.4/Frameworks/Python.framework/Versions/3.11/lib/python3.11/http/client.py", line 1286, in request
    self._send_request(method, url, body, headers, encode_chunked)
  File "/opt/homebrew/Cellar/python@3.11/3.11.4/Frameworks/Python.framework/Versions/3.11/lib/python3.11/http/client.py", line 1332, in _send_request
    self.endheaders(body, encode_chunked=encode_chunked)
  File "/opt/homebrew/Cellar/python@3.11/3.11.4/Frameworks/Python.framework/Versions/3.11/lib/python3.11/http/client.py", line 1281, in endheaders
    self._send_output(message_body, encode_chunked=encode_chunked)
  File "/opt/homebrew/Cellar/python@3.11/3.11.4/Frameworks/Python.framework/Versions/3.11/lib/python3.11/http/client.py", line 1041, in _send_output
    self.send(msg)
  File "/opt/homebrew/Cellar/python@3.11/3.11.4/Frameworks/Python.framework/Versions/3.11/lib/python3.11/http/client.py", line 979, in send
    self.connect()
  File "/opt/homebrew/Cellar/python@3.11/3.11.4/Frameworks/Python.framework/Versions/3.11/lib/python3.11/http/client.py", line 1458, in connect
    self.sock = self._context.wrap_socket(self.sock,
                ^^^^^^^^^^^^^^^^^^^^^^^^^^^^^^^^^^^^
  File "/opt/homebrew/Cellar/python@3.11/3.11.4/Frameworks/Python.framework/Versions/3.11/lib/python3.11/ssl.py", line 517, in wrap_socket
    return self.sslsocket_class._create(
           ^^^^^^^^^^^^^^^^^^^^^^^^^^^^^
  File "/opt/homebrew/Cellar/python@3.11/3.11.4/Frameworks/Python.framework/Versions/3.11/lib/python3.11/ssl.py", line 1075, in _create
    self.do_handshake()
  File "/opt/homebrew/Cellar/python@3.11/3.11.4/Frameworks/Python.framework/Versions/3.11/lib/python3.11/ssl.py", line 1346, in do_handshake
    self._sslobj.do_handshake()
ssl.SSLCertVerificationError: [SSL: CERTIFICATE_VERIFY_FAILED] certificate verify failed: unable to get local issuer certificate (_ssl.c:1002)

During handling of the above exception, another exception occurred:

Traceback (most recent call last):
  File "/opt/homebrew/bin/bpytop", line 5029, in _checker
    with urllib.request.urlopen("https://github.com/aristocratos/bpytop/raw/master/bpytop.py", timeout=5) as source: # type: ignore
         ^^^^^^^^^^^^^^^^^^^^^^^^^^^^^^^^^^^^^^^^^^^^^^^^^^^^^^^^^^^^^^^^^^^^^^^^^^^^^^^^^^^^^^^^^^^^^^^^
  File "/opt/homebrew/Cellar/python@3.11/3.11.4/Frameworks/Python.framework/Versions/3.11/lib/python3.11/urllib/request.py", line 216, in urlopen
    return opener.open(url, data, timeout)
           ^^^^^^^^^^^^^^^^^^^^^^^^^^^^^^^
  File "/opt/homebrew/Cellar/python@3.11/3.11.4/Frameworks/Python.framework/Versions/3.11/lib/python3.11/urllib/request.py", line 519, in open
    response = self._open(req, data)
               ^^^^^^^^^^^^^^^^^^^^^
  File "/opt/homebrew/Cellar/python@3.11/3.11.4/Frameworks/Python.framework/Versions/3.11/lib/python3.11/urllib/request.py", line 536, in _open
    result = self._call_chain(self.handle_open, protocol, protocol +
             ^^^^^^^^^^^^^^^^^^^^^^^^^^^^^^^^^^^^^^^^^^^^^^^^^^^^^^^
  File "/opt/homebrew/Cellar/python@3.11/3.11.4/Frameworks/Python.framework/Versions/3.11/lib/python3.11/urllib/request.py", line 496, in _call_chain
    result = func(*args)
             ^^^^^^^^^^^
  File "/opt/homebrew/Cellar/python@3.11/3.11.4/Frameworks/Python.framework/Versions/3.11/lib/python3.11/urllib/request.py", line 1391, in https_open
    return self.do_open(http.client.HTTPSConnection, req,
           ^^^^^^^^^^^^^^^^^^^^^^^^^^^^^^^^^^^^^^^^^^^^^^
  File "/opt/homebrew/Cellar/python@3.11/3.11.4/Frameworks/Python.framework/Versions/3.11/lib/python3.11/urllib/request.py", line 1351, in do_open
    raise URLError(err)
urllib.error.URLError: <urlopen error [SSL: CERTIFICATE_VERIFY_FAILED] certificate verify failed: unable to get local issuer certificate (_ssl.c:1002)>
23/06/23 (15:53:22) | ERROR: Exception while getting cpu frequency!
23/06/23 (15:53:22) | ERROR: [Errno 2] No such file or directory (originated from sysctl(HW_CPU_FREQ))
Traceback (most recent call last):
  File "/opt/homebrew/bin/bpytop", line 3080, in _collect
    if CONFIG.show_cpu_freq and hasattr(psutil.cpu_freq(), "current"):
                                        ^^^^^^^^^^^^^^^^^
  File "/opt/homebrew/Cellar/bpytop/1.0.68/libexec/lib/python3.11/site-packages/psutil/__init__.py", line 1864, in cpu_freq
    ret = _psplatform.cpu_freq()
          ^^^^^^^^^^^^^^^^^^^^^^
  File "/opt/homebrew/Cellar/bpytop/1.0.68/libexec/lib/python3.11/site-packages/psutil/_psosx.py", line 179, in cpu_freq
    curr, min_, max_ = cext.cpu_freq()
                       ^^^^^^^^^^^^^^^
FileNotFoundError: [Errno 2] No such file or directory (originated from sysctl(HW_CPU_FREQ))
23/06/23 (15:53:22) | ERROR: <urlopen error [SSL: CERTIFICATE_VERIFY_FAILED] certificate verify failed: unable to get local issuer certificate (_ssl.c:1002)>
Traceback (most recent call last):
  File "/opt/homebrew/Cellar/python@3.11/3.11.4/Frameworks/Python.framework/Versions/3.11/lib/python3.11/urllib/request.py", line 1348, in do_open
    h.request(req.get_method(), req.selector, req.data, headers,
  File "/opt/homebrew/Cellar/python@3.11/3.11.4/Frameworks/Python.framework/Versions/3.11/lib/python3.11/http/client.py", line 1286, in request
    self._send_request(method, url, body, headers, encode_chunked)
  File "/opt/homebrew/Cellar/python@3.11/3.11.4/Frameworks/Python.framework/Versions/3.11/lib/python3.11/http/client.py", line 1332, in _send_request
    self.endheaders(body, encode_chunked=encode_chunked)
  File "/opt/homebrew/Cellar/python@3.11/3.11.4/Frameworks/Python.framework/Versions/3.11/lib/python3.11/http/client.py", line 1281, in endheaders
    self._send_output(message_body, encode_chunked=encode_chunked)
  File "/opt/homebrew/Cellar/python@3.11/3.11.4/Frameworks/Python.framework/Versions/3.11/lib/python3.11/http/client.py", line 1041, in _send_output
    self.send(msg)
  File "/opt/homebrew/Cellar/python@3.11/3.11.4/Frameworks/Python.framework/Versions/3.11/lib/python3.11/http/client.py", line 979, in send
    self.connect()
  File "/opt/homebrew/Cellar/python@3.11/3.11.4/Frameworks/Python.framework/Versions/3.11/lib/python3.11/http/client.py", line 1458, in connect
    self.sock = self._context.wrap_socket(self.sock,
                ^^^^^^^^^^^^^^^^^^^^^^^^^^^^^^^^^^^^
  File "/opt/homebrew/Cellar/python@3.11/3.11.4/Frameworks/Python.framework/Versions/3.11/lib/python3.11/ssl.py", line 517, in wrap_socket
    return self.sslsocket_class._create(
           ^^^^^^^^^^^^^^^^^^^^^^^^^^^^^
  File "/opt/homebrew/Cellar/python@3.11/3.11.4/Frameworks/Python.framework/Versions/3.11/lib/python3.11/ssl.py", line 1075, in _create
    self.do_handshake()
  File "/opt/homebrew/Cellar/python@3.11/3.11.4/Frameworks/Python.framework/Versions/3.11/lib/python3.11/ssl.py", line 1346, in do_handshake
    self._sslobj.do_handshake()
ssl.SSLCertVerificationError: [SSL: CERTIFICATE_VERIFY_FAILED] certificate verify failed: unable to get local issuer certificate (_ssl.c:1002)

During handling of the above exception, another exception occurred:

Traceback (most recent call last):
  File "/opt/homebrew/bin/bpytop", line 5029, in _checker
    with urllib.request.urlopen("https://github.com/aristocratos/bpytop/raw/master/bpytop.py", timeout=5) as source: # type: ignore
         ^^^^^^^^^^^^^^^^^^^^^^^^^^^^^^^^^^^^^^^^^^^^^^^^^^^^^^^^^^^^^^^^^^^^^^^^^^^^^^^^^^^^^^^^^^^^^^^^
  File "/opt/homebrew/Cellar/python@3.11/3.11.4/Frameworks/Python.framework/Versions/3.11/lib/python3.11/urllib/request.py", line 216, in urlopen
    return opener.open(url, data, timeout)
           ^^^^^^^^^^^^^^^^^^^^^^^^^^^^^^^
  File "/opt/homebrew/Cellar/python@3.11/3.11.4/Frameworks/Python.framework/Versions/3.11/lib/python3.11/urllib/request.py", line 519, in open
    response = self._open(req, data)
               ^^^^^^^^^^^^^^^^^^^^^
  File "/opt/homebrew/Cellar/python@3.11/3.11.4/Frameworks/Python.framework/Versions/3.11/lib/python3.11/urllib/request.py", line 536, in _open
    result = self._call_chain(self.handle_open, protocol, protocol +
             ^^^^^^^^^^^^^^^^^^^^^^^^^^^^^^^^^^^^^^^^^^^^^^^^^^^^^^^
  File "/opt/homebrew/Cellar/python@3.11/3.11.4/Frameworks/Python.framework/Versions/3.11/lib/python3.11/urllib/request.py", line 496, in _call_chain
    result = func(*args)
             ^^^^^^^^^^^
  File "/opt/homebrew/Cellar/python@3.11/3.11.4/Frameworks/Python.framework/Versions/3.11/lib/python3.11/urllib/request.py", line 1391, in https_open
    return self.do_open(http.client.HTTPSConnection, req,
           ^^^^^^^^^^^^^^^^^^^^^^^^^^^^^^^^^^^^^^^^^^^^^^
  File "/opt/homebrew/Cellar/python@3.11/3.11.4/Frameworks/Python.framework/Versions/3.11/lib/python3.11/urllib/request.py", line 1351, in do_open
    raise URLError(err)
urllib.error.URLError: <urlopen error [SSL: CERTIFICATE_VERIFY_FAILED] certificate verify failed: unable to get local issuer certificate (_ssl.c:1002)>
23/06/23 (16:00:05) | ERROR: Exception while getting cpu frequency!
23/06/23 (16:00:05) | ERROR: [Errno 2] No such file or directory (originated from sysctl(HW_CPU_FREQ))
Traceback (most recent call last):
  File "/opt/homebrew/bin/bpytop", line 3080, in _collect
    if CONFIG.show_cpu_freq and hasattr(psutil.cpu_freq(), "current"):
                                        ^^^^^^^^^^^^^^^^^
  File "/opt/homebrew/Cellar/bpytop/1.0.68/libexec/lib/python3.11/site-packages/psutil/__init__.py", line 1864, in cpu_freq
    ret = _psplatform.cpu_freq()
          ^^^^^^^^^^^^^^^^^^^^^^
  File "/opt/homebrew/Cellar/bpytop/1.0.68/libexec/lib/python3.11/site-packages/psutil/_psosx.py", line 179, in cpu_freq
    curr, min_, max_ = cext.cpu_freq()
                       ^^^^^^^^^^^^^^^
FileNotFoundError: [Errno 2] No such file or directory (originated from sysctl(HW_CPU_FREQ))
23/06/23 (16:00:05) | ERROR: <urlopen error [SSL: CERTIFICATE_VERIFY_FAILED] certificate verify failed: unable to get local issuer certificate (_ssl.c:1002)>
Traceback (most recent call last):
  File "/opt/homebrew/Cellar/python@3.11/3.11.4/Frameworks/Python.framework/Versions/3.11/lib/python3.11/urllib/request.py", line 1348, in do_open
    h.request(req.get_method(), req.selector, req.data, headers,
  File "/opt/homebrew/Cellar/python@3.11/3.11.4/Frameworks/Python.framework/Versions/3.11/lib/python3.11/http/client.py", line 1286, in request
    self._send_request(method, url, body, headers, encode_chunked)
  File "/opt/homebrew/Cellar/python@3.11/3.11.4/Frameworks/Python.framework/Versions/3.11/lib/python3.11/http/client.py", line 1332, in _send_request
    self.endheaders(body, encode_chunked=encode_chunked)
  File "/opt/homebrew/Cellar/python@3.11/3.11.4/Frameworks/Python.framework/Versions/3.11/lib/python3.11/http/client.py", line 1281, in endheaders
    self._send_output(message_body, encode_chunked=encode_chunked)
  File "/opt/homebrew/Cellar/python@3.11/3.11.4/Frameworks/Python.framework/Versions/3.11/lib/python3.11/http/client.py", line 1041, in _send_output
    self.send(msg)
  File "/opt/homebrew/Cellar/python@3.11/3.11.4/Frameworks/Python.framework/Versions/3.11/lib/python3.11/http/client.py", line 979, in send
    self.connect()
  File "/opt/homebrew/Cellar/python@3.11/3.11.4/Frameworks/Python.framework/Versions/3.11/lib/python3.11/http/client.py", line 1458, in connect
    self.sock = self._context.wrap_socket(self.sock,
                ^^^^^^^^^^^^^^^^^^^^^^^^^^^^^^^^^^^^
  File "/opt/homebrew/Cellar/python@3.11/3.11.4/Frameworks/Python.framework/Versions/3.11/lib/python3.11/ssl.py", line 517, in wrap_socket
    return self.sslsocket_class._create(
           ^^^^^^^^^^^^^^^^^^^^^^^^^^^^^
  File "/opt/homebrew/Cellar/python@3.11/3.11.4/Frameworks/Python.framework/Versions/3.11/lib/python3.11/ssl.py", line 1075, in _create
    self.do_handshake()
  File "/opt/homebrew/Cellar/python@3.11/3.11.4/Frameworks/Python.framework/Versions/3.11/lib/python3.11/ssl.py", line 1346, in do_handshake
    self._sslobj.do_handshake()
ssl.SSLCertVerificationError: [SSL: CERTIFICATE_VERIFY_FAILED] certificate verify failed: unable to get local issuer certificate (_ssl.c:1002)

During handling of the above exception, another exception occurred:

Traceback (most recent call last):
  File "/opt/homebrew/bin/bpytop", line 5029, in _checker
    with urllib.request.urlopen("https://github.com/aristocratos/bpytop/raw/master/bpytop.py", timeout=5) as source: # type: ignore
         ^^^^^^^^^^^^^^^^^^^^^^^^^^^^^^^^^^^^^^^^^^^^^^^^^^^^^^^^^^^^^^^^^^^^^^^^^^^^^^^^^^^^^^^^^^^^^^^^
  File "/opt/homebrew/Cellar/python@3.11/3.11.4/Frameworks/Python.framework/Versions/3.11/lib/python3.11/urllib/request.py", line 216, in urlopen
    return opener.open(url, data, timeout)
           ^^^^^^^^^^^^^^^^^^^^^^^^^^^^^^^
  File "/opt/homebrew/Cellar/python@3.11/3.11.4/Frameworks/Python.framework/Versions/3.11/lib/python3.11/urllib/request.py", line 519, in open
    response = self._open(req, data)
               ^^^^^^^^^^^^^^^^^^^^^
  File "/opt/homebrew/Cellar/python@3.11/3.11.4/Frameworks/Python.framework/Versions/3.11/lib/python3.11/urllib/request.py", line 536, in _open
    result = self._call_chain(self.handle_open, protocol, protocol +
             ^^^^^^^^^^^^^^^^^^^^^^^^^^^^^^^^^^^^^^^^^^^^^^^^^^^^^^^
  File "/opt/homebrew/Cellar/python@3.11/3.11.4/Frameworks/Python.framework/Versions/3.11/lib/python3.11/urllib/request.py", line 496, in _call_chain
    result = func(*args)
             ^^^^^^^^^^^
  File "/opt/homebrew/Cellar/python@3.11/3.11.4/Frameworks/Python.framework/Versions/3.11/lib/python3.11/urllib/request.py", line 1391, in https_open
    return self.do_open(http.client.HTTPSConnection, req,
           ^^^^^^^^^^^^^^^^^^^^^^^^^^^^^^^^^^^^^^^^^^^^^^
  File "/opt/homebrew/Cellar/python@3.11/3.11.4/Frameworks/Python.framework/Versions/3.11/lib/python3.11/urllib/request.py", line 1351, in do_open
    raise URLError(err)
urllib.error.URLError: <urlopen error [SSL: CERTIFICATE_VERIFY_FAILED] certificate verify failed: unable to get local issuer certificate (_ssl.c:1002)>
25/06/23 (21:55:40) | ERROR: Exception while getting cpu frequency!
25/06/23 (21:55:40) | ERROR: [Errno 2] No such file or directory (originated from sysctl(HW_CPU_FREQ))
Traceback (most recent call last):
  File "/opt/homebrew/bin/bpytop", line 3080, in _collect
    if CONFIG.show_cpu_freq and hasattr(psutil.cpu_freq(), "current"):
                                        ^^^^^^^^^^^^^^^^^
  File "/opt/homebrew/Cellar/bpytop/1.0.68/libexec/lib/python3.11/site-packages/psutil/__init__.py", line 1864, in cpu_freq
    ret = _psplatform.cpu_freq()
          ^^^^^^^^^^^^^^^^^^^^^^
  File "/opt/homebrew/Cellar/bpytop/1.0.68/libexec/lib/python3.11/site-packages/psutil/_psosx.py", line 179, in cpu_freq
    curr, min_, max_ = cext.cpu_freq()
                       ^^^^^^^^^^^^^^^
FileNotFoundError: [Errno 2] No such file or directory (originated from sysctl(HW_CPU_FREQ))
25/06/23 (21:55:40) | ERROR: <urlopen error [SSL: CERTIFICATE_VERIFY_FAILED] certificate verify failed: unable to get local issuer certificate (_ssl.c:1002)>
Traceback (most recent call last):
  File "/opt/homebrew/Cellar/python@3.11/3.11.4/Frameworks/Python.framework/Versions/3.11/lib/python3.11/urllib/request.py", line 1348, in do_open
    h.request(req.get_method(), req.selector, req.data, headers,
  File "/opt/homebrew/Cellar/python@3.11/3.11.4/Frameworks/Python.framework/Versions/3.11/lib/python3.11/http/client.py", line 1286, in request
    self._send_request(method, url, body, headers, encode_chunked)
  File "/opt/homebrew/Cellar/python@3.11/3.11.4/Frameworks/Python.framework/Versions/3.11/lib/python3.11/http/client.py", line 1332, in _send_request
    self.endheaders(body, encode_chunked=encode_chunked)
  File "/opt/homebrew/Cellar/python@3.11/3.11.4/Frameworks/Python.framework/Versions/3.11/lib/python3.11/http/client.py", line 1281, in endheaders
    self._send_output(message_body, encode_chunked=encode_chunked)
  File "/opt/homebrew/Cellar/python@3.11/3.11.4/Frameworks/Python.framework/Versions/3.11/lib/python3.11/http/client.py", line 1041, in _send_output
    self.send(msg)
  File "/opt/homebrew/Cellar/python@3.11/3.11.4/Frameworks/Python.framework/Versions/3.11/lib/python3.11/http/client.py", line 979, in send
    self.connect()
  File "/opt/homebrew/Cellar/python@3.11/3.11.4/Frameworks/Python.framework/Versions/3.11/lib/python3.11/http/client.py", line 1458, in connect
    self.sock = self._context.wrap_socket(self.sock,
                ^^^^^^^^^^^^^^^^^^^^^^^^^^^^^^^^^^^^
  File "/opt/homebrew/Cellar/python@3.11/3.11.4/Frameworks/Python.framework/Versions/3.11/lib/python3.11/ssl.py", line 517, in wrap_socket
    return self.sslsocket_class._create(
           ^^^^^^^^^^^^^^^^^^^^^^^^^^^^^
  File "/opt/homebrew/Cellar/python@3.11/3.11.4/Frameworks/Python.framework/Versions/3.11/lib/python3.11/ssl.py", line 1075, in _create
    self.do_handshake()
  File "/opt/homebrew/Cellar/python@3.11/3.11.4/Frameworks/Python.framework/Versions/3.11/lib/python3.11/ssl.py", line 1346, in do_handshake
    self._sslobj.do_handshake()
ssl.SSLCertVerificationError: [SSL: CERTIFICATE_VERIFY_FAILED] certificate verify failed: unable to get local issuer certificate (_ssl.c:1002)

During handling of the above exception, another exception occurred:

Traceback (most recent call last):
  File "/opt/homebrew/bin/bpytop", line 5029, in _checker
    with urllib.request.urlopen("https://github.com/aristocratos/bpytop/raw/master/bpytop.py", timeout=5) as source: # type: ignore
         ^^^^^^^^^^^^^^^^^^^^^^^^^^^^^^^^^^^^^^^^^^^^^^^^^^^^^^^^^^^^^^^^^^^^^^^^^^^^^^^^^^^^^^^^^^^^^^^^
  File "/opt/homebrew/Cellar/python@3.11/3.11.4/Frameworks/Python.framework/Versions/3.11/lib/python3.11/urllib/request.py", line 216, in urlopen
    return opener.open(url, data, timeout)
           ^^^^^^^^^^^^^^^^^^^^^^^^^^^^^^^
  File "/opt/homebrew/Cellar/python@3.11/3.11.4/Frameworks/Python.framework/Versions/3.11/lib/python3.11/urllib/request.py", line 519, in open
    response = self._open(req, data)
               ^^^^^^^^^^^^^^^^^^^^^
  File "/opt/homebrew/Cellar/python@3.11/3.11.4/Frameworks/Python.framework/Versions/3.11/lib/python3.11/urllib/request.py", line 536, in _open
    result = self._call_chain(self.handle_open, protocol, protocol +
             ^^^^^^^^^^^^^^^^^^^^^^^^^^^^^^^^^^^^^^^^^^^^^^^^^^^^^^^
  File "/opt/homebrew/Cellar/python@3.11/3.11.4/Frameworks/Python.framework/Versions/3.11/lib/python3.11/urllib/request.py", line 496, in _call_chain
    result = func(*args)
             ^^^^^^^^^^^
  File "/opt/homebrew/Cellar/python@3.11/3.11.4/Frameworks/Python.framework/Versions/3.11/lib/python3.11/urllib/request.py", line 1391, in https_open
    return self.do_open(http.client.HTTPSConnection, req,
           ^^^^^^^^^^^^^^^^^^^^^^^^^^^^^^^^^^^^^^^^^^^^^^
  File "/opt/homebrew/Cellar/python@3.11/3.11.4/Frameworks/Python.framework/Versions/3.11/lib/python3.11/urllib/request.py", line 1351, in do_open
    raise URLError(err)
urllib.error.URLError: <urlopen error [SSL: CERTIFICATE_VERIFY_FAILED] certificate verify failed: unable to get local issuer certificate (_ssl.c:1002)>
26/06/23 (14:20:26) | ERROR: Exception while getting cpu frequency!
26/06/23 (14:20:26) | ERROR: [Errno 2] No such file or directory (originated from sysctl(HW_CPU_FREQ))
Traceback (most recent call last):
  File "/opt/homebrew/bin/bpytop", line 3080, in _collect
    if CONFIG.show_cpu_freq and hasattr(psutil.cpu_freq(), "current"):
                                        ^^^^^^^^^^^^^^^^^
  File "/opt/homebrew/Cellar/bpytop/1.0.68/libexec/lib/python3.11/site-packages/psutil/__init__.py", line 1864, in cpu_freq
    ret = _psplatform.cpu_freq()
          ^^^^^^^^^^^^^^^^^^^^^^
  File "/opt/homebrew/Cellar/bpytop/1.0.68/libexec/lib/python3.11/site-packages/psutil/_psosx.py", line 179, in cpu_freq
    curr, min_, max_ = cext.cpu_freq()
                       ^^^^^^^^^^^^^^^
FileNotFoundError: [Errno 2] No such file or directory (originated from sysctl(HW_CPU_FREQ))
26/06/23 (14:20:26) | ERROR: <urlopen error [SSL: CERTIFICATE_VERIFY_FAILED] certificate verify failed: unable to get local issuer certificate (_ssl.c:1002)>
Traceback (most recent call last):
  File "/opt/homebrew/Cellar/python@3.11/3.11.4/Frameworks/Python.framework/Versions/3.11/lib/python3.11/urllib/request.py", line 1348, in do_open
    h.request(req.get_method(), req.selector, req.data, headers,
  File "/opt/homebrew/Cellar/python@3.11/3.11.4/Frameworks/Python.framework/Versions/3.11/lib/python3.11/http/client.py", line 1286, in request
    self._send_request(method, url, body, headers, encode_chunked)
  File "/opt/homebrew/Cellar/python@3.11/3.11.4/Frameworks/Python.framework/Versions/3.11/lib/python3.11/http/client.py", line 1332, in _send_request
    self.endheaders(body, encode_chunked=encode_chunked)
  File "/opt/homebrew/Cellar/python@3.11/3.11.4/Frameworks/Python.framework/Versions/3.11/lib/python3.11/http/client.py", line 1281, in endheaders
    self._send_output(message_body, encode_chunked=encode_chunked)
  File "/opt/homebrew/Cellar/python@3.11/3.11.4/Frameworks/Python.framework/Versions/3.11/lib/python3.11/http/client.py", line 1041, in _send_output
    self.send(msg)
  File "/opt/homebrew/Cellar/python@3.11/3.11.4/Frameworks/Python.framework/Versions/3.11/lib/python3.11/http/client.py", line 979, in send
    self.connect()
  File "/opt/homebrew/Cellar/python@3.11/3.11.4/Frameworks/Python.framework/Versions/3.11/lib/python3.11/http/client.py", line 1458, in connect
    self.sock = self._context.wrap_socket(self.sock,
                ^^^^^^^^^^^^^^^^^^^^^^^^^^^^^^^^^^^^
  File "/opt/homebrew/Cellar/python@3.11/3.11.4/Frameworks/Python.framework/Versions/3.11/lib/python3.11/ssl.py", line 517, in wrap_socket
    return self.sslsocket_class._create(
           ^^^^^^^^^^^^^^^^^^^^^^^^^^^^^
  File "/opt/homebrew/Cellar/python@3.11/3.11.4/Frameworks/Python.framework/Versions/3.11/lib/python3.11/ssl.py", line 1075, in _create
    self.do_handshake()
  File "/opt/homebrew/Cellar/python@3.11/3.11.4/Frameworks/Python.framework/Versions/3.11/lib/python3.11/ssl.py", line 1346, in do_handshake
    self._sslobj.do_handshake()
ssl.SSLCertVerificationError: [SSL: CERTIFICATE_VERIFY_FAILED] certificate verify failed: unable to get local issuer certificate (_ssl.c:1002)

During handling of the above exception, another exception occurred:

Traceback (most recent call last):
  File "/opt/homebrew/bin/bpytop", line 5029, in _checker
    with urllib.request.urlopen("https://github.com/aristocratos/bpytop/raw/master/bpytop.py", timeout=5) as source: # type: ignore
         ^^^^^^^^^^^^^^^^^^^^^^^^^^^^^^^^^^^^^^^^^^^^^^^^^^^^^^^^^^^^^^^^^^^^^^^^^^^^^^^^^^^^^^^^^^^^^^^^
  File "/opt/homebrew/Cellar/python@3.11/3.11.4/Frameworks/Python.framework/Versions/3.11/lib/python3.11/urllib/request.py", line 216, in urlopen
    return opener.open(url, data, timeout)
           ^^^^^^^^^^^^^^^^^^^^^^^^^^^^^^^
  File "/opt/homebrew/Cellar/python@3.11/3.11.4/Frameworks/Python.framework/Versions/3.11/lib/python3.11/urllib/request.py", line 519, in open
    response = self._open(req, data)
               ^^^^^^^^^^^^^^^^^^^^^
  File "/opt/homebrew/Cellar/python@3.11/3.11.4/Frameworks/Python.framework/Versions/3.11/lib/python3.11/urllib/request.py", line 536, in _open
    result = self._call_chain(self.handle_open, protocol, protocol +
             ^^^^^^^^^^^^^^^^^^^^^^^^^^^^^^^^^^^^^^^^^^^^^^^^^^^^^^^
  File "/opt/homebrew/Cellar/python@3.11/3.11.4/Frameworks/Python.framework/Versions/3.11/lib/python3.11/urllib/request.py", line 496, in _call_chain
    result = func(*args)
             ^^^^^^^^^^^
  File "/opt/homebrew/Cellar/python@3.11/3.11.4/Frameworks/Python.framework/Versions/3.11/lib/python3.11/urllib/request.py", line 1391, in https_open
    return self.do_open(http.client.HTTPSConnection, req,
           ^^^^^^^^^^^^^^^^^^^^^^^^^^^^^^^^^^^^^^^^^^^^^^
  File "/opt/homebrew/Cellar/python@3.11/3.11.4/Frameworks/Python.framework/Versions/3.11/lib/python3.11/urllib/request.py", line 1351, in do_open
    raise URLError(err)
urllib.error.URLError: <urlopen error [SSL: CERTIFICATE_VERIFY_FAILED] certificate verify failed: unable to get local issuer certificate (_ssl.c:1002)>
26/06/23 (14:21:14) | ERROR: Exception while getting cpu frequency!
26/06/23 (14:21:14) | ERROR: [Errno 2] No such file or directory (originated from sysctl(HW_CPU_FREQ))
Traceback (most recent call last):
  File "/opt/homebrew/bin/bpytop", line 3080, in _collect
    if CONFIG.show_cpu_freq and hasattr(psutil.cpu_freq(), "current"):
                                        ^^^^^^^^^^^^^^^^^
  File "/opt/homebrew/Cellar/bpytop/1.0.68/libexec/lib/python3.11/site-packages/psutil/__init__.py", line 1864, in cpu_freq
    ret = _psplatform.cpu_freq()
          ^^^^^^^^^^^^^^^^^^^^^^
  File "/opt/homebrew/Cellar/bpytop/1.0.68/libexec/lib/python3.11/site-packages/psutil/_psosx.py", line 179, in cpu_freq
    curr, min_, max_ = cext.cpu_freq()
                       ^^^^^^^^^^^^^^^
FileNotFoundError: [Errno 2] No such file or directory (originated from sysctl(HW_CPU_FREQ))
26/06/23 (14:21:14) | ERROR: <urlopen error [SSL: CERTIFICATE_VERIFY_FAILED] certificate verify failed: unable to get local issuer certificate (_ssl.c:1002)>
Traceback (most recent call last):
  File "/opt/homebrew/Cellar/python@3.11/3.11.4/Frameworks/Python.framework/Versions/3.11/lib/python3.11/urllib/request.py", line 1348, in do_open
    h.request(req.get_method(), req.selector, req.data, headers,
  File "/opt/homebrew/Cellar/python@3.11/3.11.4/Frameworks/Python.framework/Versions/3.11/lib/python3.11/http/client.py", line 1286, in request
    self._send_request(method, url, body, headers, encode_chunked)
  File "/opt/homebrew/Cellar/python@3.11/3.11.4/Frameworks/Python.framework/Versions/3.11/lib/python3.11/http/client.py", line 1332, in _send_request
    self.endheaders(body, encode_chunked=encode_chunked)
  File "/opt/homebrew/Cellar/python@3.11/3.11.4/Frameworks/Python.framework/Versions/3.11/lib/python3.11/http/client.py", line 1281, in endheaders
    self._send_output(message_body, encode_chunked=encode_chunked)
  File "/opt/homebrew/Cellar/python@3.11/3.11.4/Frameworks/Python.framework/Versions/3.11/lib/python3.11/http/client.py", line 1041, in _send_output
    self.send(msg)
  File "/opt/homebrew/Cellar/python@3.11/3.11.4/Frameworks/Python.framework/Versions/3.11/lib/python3.11/http/client.py", line 979, in send
    self.connect()
  File "/opt/homebrew/Cellar/python@3.11/3.11.4/Frameworks/Python.framework/Versions/3.11/lib/python3.11/http/client.py", line 1458, in connect
    self.sock = self._context.wrap_socket(self.sock,
                ^^^^^^^^^^^^^^^^^^^^^^^^^^^^^^^^^^^^
  File "/opt/homebrew/Cellar/python@3.11/3.11.4/Frameworks/Python.framework/Versions/3.11/lib/python3.11/ssl.py", line 517, in wrap_socket
    return self.sslsocket_class._create(
           ^^^^^^^^^^^^^^^^^^^^^^^^^^^^^
  File "/opt/homebrew/Cellar/python@3.11/3.11.4/Frameworks/Python.framework/Versions/3.11/lib/python3.11/ssl.py", line 1075, in _create
    self.do_handshake()
  File "/opt/homebrew/Cellar/python@3.11/3.11.4/Frameworks/Python.framework/Versions/3.11/lib/python3.11/ssl.py", line 1346, in do_handshake
    self._sslobj.do_handshake()
ssl.SSLCertVerificationError: [SSL: CERTIFICATE_VERIFY_FAILED] certificate verify failed: unable to get local issuer certificate (_ssl.c:1002)

During handling of the above exception, another exception occurred:

Traceback (most recent call last):
  File "/opt/homebrew/bin/bpytop", line 5029, in _checker
    with urllib.request.urlopen("https://github.com/aristocratos/bpytop/raw/master/bpytop.py", timeout=5) as source: # type: ignore
         ^^^^^^^^^^^^^^^^^^^^^^^^^^^^^^^^^^^^^^^^^^^^^^^^^^^^^^^^^^^^^^^^^^^^^^^^^^^^^^^^^^^^^^^^^^^^^^^^
  File "/opt/homebrew/Cellar/python@3.11/3.11.4/Frameworks/Python.framework/Versions/3.11/lib/python3.11/urllib/request.py", line 216, in urlopen
    return opener.open(url, data, timeout)
           ^^^^^^^^^^^^^^^^^^^^^^^^^^^^^^^
  File "/opt/homebrew/Cellar/python@3.11/3.11.4/Frameworks/Python.framework/Versions/3.11/lib/python3.11/urllib/request.py", line 519, in open
    response = self._open(req, data)
               ^^^^^^^^^^^^^^^^^^^^^
  File "/opt/homebrew/Cellar/python@3.11/3.11.4/Frameworks/Python.framework/Versions/3.11/lib/python3.11/urllib/request.py", line 536, in _open
    result = self._call_chain(self.handle_open, protocol, protocol +
             ^^^^^^^^^^^^^^^^^^^^^^^^^^^^^^^^^^^^^^^^^^^^^^^^^^^^^^^
  File "/opt/homebrew/Cellar/python@3.11/3.11.4/Frameworks/Python.framework/Versions/3.11/lib/python3.11/urllib/request.py", line 496, in _call_chain
    result = func(*args)
             ^^^^^^^^^^^
  File "/opt/homebrew/Cellar/python@3.11/3.11.4/Frameworks/Python.framework/Versions/3.11/lib/python3.11/urllib/request.py", line 1391, in https_open
    return self.do_open(http.client.HTTPSConnection, req,
           ^^^^^^^^^^^^^^^^^^^^^^^^^^^^^^^^^^^^^^^^^^^^^^
  File "/opt/homebrew/Cellar/python@3.11/3.11.4/Frameworks/Python.framework/Versions/3.11/lib/python3.11/urllib/request.py", line 1351, in do_open
    raise URLError(err)
urllib.error.URLError: <urlopen error [SSL: CERTIFICATE_VERIFY_FAILED] certificate verify failed: unable to get local issuer certificate (_ssl.c:1002)>
27/06/23 (15:48:38) | ERROR: Exception while getting cpu frequency!
27/06/23 (15:48:38) | ERROR: [Errno 2] No such file or directory (originated from sysctl(HW_CPU_FREQ))
Traceback (most recent call last):
  File "/opt/homebrew/bin/bpytop", line 3080, in _collect
    if CONFIG.show_cpu_freq and hasattr(psutil.cpu_freq(), "current"):
                                        ^^^^^^^^^^^^^^^^^
  File "/opt/homebrew/Cellar/bpytop/1.0.68/libexec/lib/python3.11/site-packages/psutil/__init__.py", line 1864, in cpu_freq
    ret = _psplatform.cpu_freq()
          ^^^^^^^^^^^^^^^^^^^^^^
  File "/opt/homebrew/Cellar/bpytop/1.0.68/libexec/lib/python3.11/site-packages/psutil/_psosx.py", line 179, in cpu_freq
    curr, min_, max_ = cext.cpu_freq()
                       ^^^^^^^^^^^^^^^
FileNotFoundError: [Errno 2] No such file or directory (originated from sysctl(HW_CPU_FREQ))
28/06/23 (17:30:54) | ERROR: Exception while getting cpu frequency!
28/06/23 (17:30:54) | ERROR: [Errno 2] No such file or directory (originated from sysctl(HW_CPU_FREQ))
Traceback (most recent call last):
  File "/opt/homebrew/bin/bpytop", line 3080, in _collect
    if CONFIG.show_cpu_freq and hasattr(psutil.cpu_freq(), "current"):
                                        ^^^^^^^^^^^^^^^^^
  File "/opt/homebrew/Cellar/bpytop/1.0.68/libexec/lib/python3.11/site-packages/psutil/__init__.py", line 1864, in cpu_freq
    ret = _psplatform.cpu_freq()
          ^^^^^^^^^^^^^^^^^^^^^^
  File "/opt/homebrew/Cellar/bpytop/1.0.68/libexec/lib/python3.11/site-packages/psutil/_psosx.py", line 179, in cpu_freq
    curr, min_, max_ = cext.cpu_freq()
                       ^^^^^^^^^^^^^^^
FileNotFoundError: [Errno 2] No such file or directory (originated from sysctl(HW_CPU_FREQ))
28/06/23 (19:41:21) | ERROR: Exception while getting cpu frequency!
28/06/23 (19:41:21) | ERROR: [Errno 2] No such file or directory (originated from sysctl(HW_CPU_FREQ))
Traceback (most recent call last):
  File "/opt/homebrew/bin/bpytop", line 3080, in _collect
    if CONFIG.show_cpu_freq and hasattr(psutil.cpu_freq(), "current"):
                                        ^^^^^^^^^^^^^^^^^
  File "/opt/homebrew/Cellar/bpytop/1.0.68/libexec/lib/python3.11/site-packages/psutil/__init__.py", line 1864, in cpu_freq
    ret = _psplatform.cpu_freq()
          ^^^^^^^^^^^^^^^^^^^^^^
  File "/opt/homebrew/Cellar/bpytop/1.0.68/libexec/lib/python3.11/site-packages/psutil/_psosx.py", line 179, in cpu_freq
    curr, min_, max_ = cext.cpu_freq()
                       ^^^^^^^^^^^^^^^
FileNotFoundError: [Errno 2] No such file or directory (originated from sysctl(HW_CPU_FREQ))
01/07/23 (12:27:53) | ERROR: Exception while getting cpu frequency!
01/07/23 (12:27:53) | ERROR: [Errno 2] No such file or directory (originated from sysctl(HW_CPU_FREQ))
Traceback (most recent call last):
  File "/opt/homebrew/bin/bpytop", line 3080, in _collect
    if CONFIG.show_cpu_freq and hasattr(psutil.cpu_freq(), "current"):
                                        ^^^^^^^^^^^^^^^^^
  File "/opt/homebrew/Cellar/bpytop/1.0.68/libexec/lib/python3.11/site-packages/psutil/__init__.py", line 1864, in cpu_freq
    ret = _psplatform.cpu_freq()
          ^^^^^^^^^^^^^^^^^^^^^^
  File "/opt/homebrew/Cellar/bpytop/1.0.68/libexec/lib/python3.11/site-packages/psutil/_psosx.py", line 179, in cpu_freq
    curr, min_, max_ = cext.cpu_freq()
                       ^^^^^^^^^^^^^^^
FileNotFoundError: [Errno 2] No such file or directory (originated from sysctl(HW_CPU_FREQ))
01/07/23 (13:31:51) | ERROR: Exception while getting cpu frequency!
01/07/23 (13:31:51) | ERROR: [Errno 2] No such file or directory (originated from sysctl(HW_CPU_FREQ))
Traceback (most recent call last):
  File "/opt/homebrew/bin/bpytop", line 3080, in _collect
    if CONFIG.show_cpu_freq and hasattr(psutil.cpu_freq(), "current"):
                                        ^^^^^^^^^^^^^^^^^
  File "/opt/homebrew/Cellar/bpytop/1.0.68/libexec/lib/python3.11/site-packages/psutil/__init__.py", line 1864, in cpu_freq
    ret = _psplatform.cpu_freq()
          ^^^^^^^^^^^^^^^^^^^^^^
  File "/opt/homebrew/Cellar/bpytop/1.0.68/libexec/lib/python3.11/site-packages/psutil/_psosx.py", line 179, in cpu_freq
    curr, min_, max_ = cext.cpu_freq()
                       ^^^^^^^^^^^^^^^
FileNotFoundError: [Errno 2] No such file or directory (originated from sysctl(HW_CPU_FREQ))
01/07/23 (14:24:20) | ERROR: Exception while getting cpu frequency!
01/07/23 (14:24:20) | ERROR: [Errno 2] No such file or directory (originated from sysctl(HW_CPU_FREQ))
Traceback (most recent call last):
  File "/opt/homebrew/bin/bpytop", line 3080, in _collect
    if CONFIG.show_cpu_freq and hasattr(psutil.cpu_freq(), "current"):
                                        ^^^^^^^^^^^^^^^^^
  File "/opt/homebrew/Cellar/bpytop/1.0.68/libexec/lib/python3.11/site-packages/psutil/__init__.py", line 1864, in cpu_freq
    ret = _psplatform.cpu_freq()
          ^^^^^^^^^^^^^^^^^^^^^^
  File "/opt/homebrew/Cellar/bpytop/1.0.68/libexec/lib/python3.11/site-packages/psutil/_psosx.py", line 179, in cpu_freq
    curr, min_, max_ = cext.cpu_freq()
                       ^^^^^^^^^^^^^^^
FileNotFoundError: [Errno 2] No such file or directory (originated from sysctl(HW_CPU_FREQ))
01/07/23 (14:24:40) | ERROR: The read operation timed out
Traceback (most recent call last):
  File "/opt/homebrew/bin/bpytop", line 5029, in _checker
    with urllib.request.urlopen("https://github.com/aristocratos/bpytop/raw/master/bpytop.py", timeout=5) as source: # type: ignore
         ^^^^^^^^^^^^^^^^^^^^^^^^^^^^^^^^^^^^^^^^^^^^^^^^^^^^^^^^^^^^^^^^^^^^^^^^^^^^^^^^^^^^^^^^^^^^^^^^
  File "/opt/homebrew/Cellar/python@3.11/3.11.4_1/Frameworks/Python.framework/Versions/3.11/lib/python3.11/urllib/request.py", line 216, in urlopen
    return opener.open(url, data, timeout)
           ^^^^^^^^^^^^^^^^^^^^^^^^^^^^^^^
  File "/opt/homebrew/Cellar/python@3.11/3.11.4_1/Frameworks/Python.framework/Versions/3.11/lib/python3.11/urllib/request.py", line 525, in open
    response = meth(req, response)
               ^^^^^^^^^^^^^^^^^^^
  File "/opt/homebrew/Cellar/python@3.11/3.11.4_1/Frameworks/Python.framework/Versions/3.11/lib/python3.11/urllib/request.py", line 634, in http_response
    response = self.parent.error(
               ^^^^^^^^^^^^^^^^^^
  File "/opt/homebrew/Cellar/python@3.11/3.11.4_1/Frameworks/Python.framework/Versions/3.11/lib/python3.11/urllib/request.py", line 557, in error
    result = self._call_chain(*args)
             ^^^^^^^^^^^^^^^^^^^^^^^
  File "/opt/homebrew/Cellar/python@3.11/3.11.4_1/Frameworks/Python.framework/Versions/3.11/lib/python3.11/urllib/request.py", line 496, in _call_chain
    result = func(*args)
             ^^^^^^^^^^^
  File "/opt/homebrew/Cellar/python@3.11/3.11.4_1/Frameworks/Python.framework/Versions/3.11/lib/python3.11/urllib/request.py", line 749, in http_error_302
    return self.parent.open(new, timeout=req.timeout)
           ^^^^^^^^^^^^^^^^^^^^^^^^^^^^^^^^^^^^^^^^^^
  File "/opt/homebrew/Cellar/python@3.11/3.11.4_1/Frameworks/Python.framework/Versions/3.11/lib/python3.11/urllib/request.py", line 519, in open
    response = self._open(req, data)
               ^^^^^^^^^^^^^^^^^^^^^
  File "/opt/homebrew/Cellar/python@3.11/3.11.4_1/Frameworks/Python.framework/Versions/3.11/lib/python3.11/urllib/request.py", line 536, in _open
    result = self._call_chain(self.handle_open, protocol, protocol +
             ^^^^^^^^^^^^^^^^^^^^^^^^^^^^^^^^^^^^^^^^^^^^^^^^^^^^^^^
  File "/opt/homebrew/Cellar/python@3.11/3.11.4_1/Frameworks/Python.framework/Versions/3.11/lib/python3.11/urllib/request.py", line 496, in _call_chain
    result = func(*args)
             ^^^^^^^^^^^
  File "/opt/homebrew/Cellar/python@3.11/3.11.4_1/Frameworks/Python.framework/Versions/3.11/lib/python3.11/urllib/request.py", line 1391, in https_open
    return self.do_open(http.client.HTTPSConnection, req,
           ^^^^^^^^^^^^^^^^^^^^^^^^^^^^^^^^^^^^^^^^^^^^^^
  File "/opt/homebrew/Cellar/python@3.11/3.11.4_1/Frameworks/Python.framework/Versions/3.11/lib/python3.11/urllib/request.py", line 1352, in do_open
    r = h.getresponse()
        ^^^^^^^^^^^^^^^
  File "/opt/homebrew/Cellar/python@3.11/3.11.4_1/Frameworks/Python.framework/Versions/3.11/lib/python3.11/http/client.py", line 1378, in getresponse
    response.begin()
  File "/opt/homebrew/Cellar/python@3.11/3.11.4_1/Frameworks/Python.framework/Versions/3.11/lib/python3.11/http/client.py", line 318, in begin
    version, status, reason = self._read_status()
                              ^^^^^^^^^^^^^^^^^^^
  File "/opt/homebrew/Cellar/python@3.11/3.11.4_1/Frameworks/Python.framework/Versions/3.11/lib/python3.11/http/client.py", line 279, in _read_status
    line = str(self.fp.readline(_MAXLINE + 1), "iso-8859-1")
               ^^^^^^^^^^^^^^^^^^^^^^^^^^^^^^
  File "/opt/homebrew/Cellar/python@3.11/3.11.4_1/Frameworks/Python.framework/Versions/3.11/lib/python3.11/socket.py", line 706, in readinto
    return self._sock.recv_into(b)
           ^^^^^^^^^^^^^^^^^^^^^^^
  File "/opt/homebrew/Cellar/python@3.11/3.11.4_1/Frameworks/Python.framework/Versions/3.11/lib/python3.11/ssl.py", line 1278, in recv_into
    return self.read(nbytes, buffer)
           ^^^^^^^^^^^^^^^^^^^^^^^^^
  File "/opt/homebrew/Cellar/python@3.11/3.11.4_1/Frameworks/Python.framework/Versions/3.11/lib/python3.11/ssl.py", line 1134, in read
    return self._sslobj.read(len, buffer)
           ^^^^^^^^^^^^^^^^^^^^^^^^^^^^^^
TimeoutError: The read operation timed out
05/07/23 (18:33:55) | ERROR: Exception while getting cpu frequency!
05/07/23 (18:33:55) | ERROR: [Errno 2] No such file or directory (originated from sysctl(HW_CPU_FREQ))
Traceback (most recent call last):
  File "/opt/homebrew/bin/bpytop", line 3080, in _collect
    if CONFIG.show_cpu_freq and hasattr(psutil.cpu_freq(), "current"):
                                        ^^^^^^^^^^^^^^^^^
  File "/opt/homebrew/Cellar/bpytop/1.0.68/libexec/lib/python3.11/site-packages/psutil/__init__.py", line 1864, in cpu_freq
    ret = _psplatform.cpu_freq()
          ^^^^^^^^^^^^^^^^^^^^^^
  File "/opt/homebrew/Cellar/bpytop/1.0.68/libexec/lib/python3.11/site-packages/psutil/_psosx.py", line 179, in cpu_freq
    curr, min_, max_ = cext.cpu_freq()
                       ^^^^^^^^^^^^^^^
FileNotFoundError: [Errno 2] No such file or directory (originated from sysctl(HW_CPU_FREQ))
05/07/23 (19:19:44) | ERROR: Exception while getting cpu frequency!
05/07/23 (19:19:44) | ERROR: [Errno 2] No such file or directory (originated from sysctl(HW_CPU_FREQ))
Traceback (most recent call last):
  File "/opt/homebrew/bin/bpytop", line 3080, in _collect
    if CONFIG.show_cpu_freq and hasattr(psutil.cpu_freq(), "current"):
                                        ^^^^^^^^^^^^^^^^^
  File "/opt/homebrew/Cellar/bpytop/1.0.68/libexec/lib/python3.11/site-packages/psutil/__init__.py", line 1864, in cpu_freq
    ret = _psplatform.cpu_freq()
          ^^^^^^^^^^^^^^^^^^^^^^
  File "/opt/homebrew/Cellar/bpytop/1.0.68/libexec/lib/python3.11/site-packages/psutil/_psosx.py", line 179, in cpu_freq
    curr, min_, max_ = cext.cpu_freq()
                       ^^^^^^^^^^^^^^^
FileNotFoundError: [Errno 2] No such file or directory (originated from sysctl(HW_CPU_FREQ))
07/07/23 (12:37:17) | ERROR: Exception while getting cpu frequency!
07/07/23 (12:37:17) | ERROR: [Errno 2] No such file or directory (originated from sysctl(HW_CPU_FREQ))
Traceback (most recent call last):
  File "/opt/homebrew/bin/bpytop", line 3080, in _collect
    if CONFIG.show_cpu_freq and hasattr(psutil.cpu_freq(), "current"):
                                        ^^^^^^^^^^^^^^^^^
  File "/opt/homebrew/Cellar/bpytop/1.0.68/libexec/lib/python3.11/site-packages/psutil/__init__.py", line 1864, in cpu_freq
    ret = _psplatform.cpu_freq()
          ^^^^^^^^^^^^^^^^^^^^^^
  File "/opt/homebrew/Cellar/bpytop/1.0.68/libexec/lib/python3.11/site-packages/psutil/_psosx.py", line 179, in cpu_freq
    curr, min_, max_ = cext.cpu_freq()
                       ^^^^^^^^^^^^^^^
FileNotFoundError: [Errno 2] No such file or directory (originated from sysctl(HW_CPU_FREQ))
09/07/23 (13:24:43) | ERROR: Exception while getting cpu frequency!
09/07/23 (13:24:43) | ERROR: [Errno 2] No such file or directory (originated from sysctl(HW_CPU_FREQ))
Traceback (most recent call last):
  File "/opt/homebrew/bin/bpytop", line 3080, in _collect
    if CONFIG.show_cpu_freq and hasattr(psutil.cpu_freq(), "current"):
                                        ^^^^^^^^^^^^^^^^^
  File "/opt/homebrew/Cellar/bpytop/1.0.68/libexec/lib/python3.11/site-packages/psutil/__init__.py", line 1864, in cpu_freq
    ret = _psplatform.cpu_freq()
          ^^^^^^^^^^^^^^^^^^^^^^
  File "/opt/homebrew/Cellar/bpytop/1.0.68/libexec/lib/python3.11/site-packages/psutil/_psosx.py", line 179, in cpu_freq
    curr, min_, max_ = cext.cpu_freq()
                       ^^^^^^^^^^^^^^^
FileNotFoundError: [Errno 2] No such file or directory (originated from sysctl(HW_CPU_FREQ))
09/07/23 (15:18:14) | ERROR: Exception while getting cpu frequency!
09/07/23 (15:18:14) | ERROR: [Errno 2] No such file or directory (originated from sysctl(HW_CPU_FREQ))
Traceback (most recent call last):
  File "/opt/homebrew/bin/bpytop", line 3080, in _collect
    if CONFIG.show_cpu_freq and hasattr(psutil.cpu_freq(), "current"):
                                        ^^^^^^^^^^^^^^^^^
  File "/opt/homebrew/Cellar/bpytop/1.0.68/libexec/lib/python3.11/site-packages/psutil/__init__.py", line 1864, in cpu_freq
    ret = _psplatform.cpu_freq()
          ^^^^^^^^^^^^^^^^^^^^^^
  File "/opt/homebrew/Cellar/bpytop/1.0.68/libexec/lib/python3.11/site-packages/psutil/_psosx.py", line 179, in cpu_freq
    curr, min_, max_ = cext.cpu_freq()
                       ^^^^^^^^^^^^^^^
FileNotFoundError: [Errno 2] No such file or directory (originated from sysctl(HW_CPU_FREQ))
09/07/23 (15:19:56) | ERROR: Exception while getting cpu frequency!
09/07/23 (15:19:56) | ERROR: [Errno 2] No such file or directory (originated from sysctl(HW_CPU_FREQ))
Traceback (most recent call last):
  File "/opt/homebrew/bin/bpytop", line 3080, in _collect
    if CONFIG.show_cpu_freq and hasattr(psutil.cpu_freq(), "current"):
                                        ^^^^^^^^^^^^^^^^^
  File "/opt/homebrew/Cellar/bpytop/1.0.68/libexec/lib/python3.11/site-packages/psutil/__init__.py", line 1864, in cpu_freq
    ret = _psplatform.cpu_freq()
          ^^^^^^^^^^^^^^^^^^^^^^
  File "/opt/homebrew/Cellar/bpytop/1.0.68/libexec/lib/python3.11/site-packages/psutil/_psosx.py", line 179, in cpu_freq
    curr, min_, max_ = cext.cpu_freq()
                       ^^^^^^^^^^^^^^^
FileNotFoundError: [Errno 2] No such file or directory (originated from sysctl(HW_CPU_FREQ))
10/07/23 (02:45:12) | ERROR: Exception while getting cpu frequency!
10/07/23 (02:45:12) | ERROR: [Errno 2] No such file or directory (originated from sysctl(HW_CPU_FREQ))
Traceback (most recent call last):
  File "/opt/homebrew/bin/bpytop", line 3080, in _collect
    if CONFIG.show_cpu_freq and hasattr(psutil.cpu_freq(), "current"):
                                        ^^^^^^^^^^^^^^^^^
  File "/opt/homebrew/Cellar/bpytop/1.0.68/libexec/lib/python3.11/site-packages/psutil/__init__.py", line 1864, in cpu_freq
    ret = _psplatform.cpu_freq()
          ^^^^^^^^^^^^^^^^^^^^^^
  File "/opt/homebrew/Cellar/bpytop/1.0.68/libexec/lib/python3.11/site-packages/psutil/_psosx.py", line 179, in cpu_freq
    curr, min_, max_ = cext.cpu_freq()
                       ^^^^^^^^^^^^^^^
FileNotFoundError: [Errno 2] No such file or directory (originated from sysctl(HW_CPU_FREQ))
10/07/23 (02:45:58) | ERROR: Exception while getting cpu frequency!
10/07/23 (02:45:58) | ERROR: [Errno 2] No such file or directory (originated from sysctl(HW_CPU_FREQ))
Traceback (most recent call last):
  File "/opt/homebrew/bin/bpytop", line 3080, in _collect
    if CONFIG.show_cpu_freq and hasattr(psutil.cpu_freq(), "current"):
                                        ^^^^^^^^^^^^^^^^^
  File "/opt/homebrew/Cellar/bpytop/1.0.68/libexec/lib/python3.11/site-packages/psutil/__init__.py", line 1864, in cpu_freq
    ret = _psplatform.cpu_freq()
          ^^^^^^^^^^^^^^^^^^^^^^
  File "/opt/homebrew/Cellar/bpytop/1.0.68/libexec/lib/python3.11/site-packages/psutil/_psosx.py", line 179, in cpu_freq
    curr, min_, max_ = cext.cpu_freq()
                       ^^^^^^^^^^^^^^^
FileNotFoundError: [Errno 2] No such file or directory (originated from sysctl(HW_CPU_FREQ))
10/07/23 (02:59:21) | ERROR: Exception while getting cpu frequency!
10/07/23 (02:59:21) | ERROR: [Errno 2] No such file or directory (originated from sysctl(HW_CPU_FREQ))
Traceback (most recent call last):
  File "/opt/homebrew/bin/bpytop", line 3080, in _collect
    if CONFIG.show_cpu_freq and hasattr(psutil.cpu_freq(), "current"):
                                        ^^^^^^^^^^^^^^^^^
  File "/opt/homebrew/Cellar/bpytop/1.0.68/libexec/lib/python3.11/site-packages/psutil/__init__.py", line 1864, in cpu_freq
    ret = _psplatform.cpu_freq()
          ^^^^^^^^^^^^^^^^^^^^^^
  File "/opt/homebrew/Cellar/bpytop/1.0.68/libexec/lib/python3.11/site-packages/psutil/_psosx.py", line 179, in cpu_freq
    curr, min_, max_ = cext.cpu_freq()
                       ^^^^^^^^^^^^^^^
FileNotFoundError: [Errno 2] No such file or directory (originated from sysctl(HW_CPU_FREQ))
18/07/23 (21:16:22) | ERROR: Exception while getting cpu frequency!
18/07/23 (21:16:22) | ERROR: [Errno 2] No such file or directory (originated from sysctl(HW_CPU_FREQ))
Traceback (most recent call last):
  File "/opt/homebrew/bin/bpytop", line 3080, in _collect
    if CONFIG.show_cpu_freq and hasattr(psutil.cpu_freq(), "current"):
                                        ^^^^^^^^^^^^^^^^^
  File "/opt/homebrew/Cellar/bpytop/1.0.68/libexec/lib/python3.11/site-packages/psutil/__init__.py", line 1864, in cpu_freq
    ret = _psplatform.cpu_freq()
          ^^^^^^^^^^^^^^^^^^^^^^
  File "/opt/homebrew/Cellar/bpytop/1.0.68/libexec/lib/python3.11/site-packages/psutil/_psosx.py", line 179, in cpu_freq
    curr, min_, max_ = cext.cpu_freq()
                       ^^^^^^^^^^^^^^^
FileNotFoundError: [Errno 2] No such file or directory (originated from sysctl(HW_CPU_FREQ))
30/09/23 (13:56:34) | ERROR: Exception while getting cpu frequency!
30/09/23 (13:56:34) | ERROR: [Errno 2] No such file or directory (originated from sysctl(HW_CPU_FREQ))
Traceback (most recent call last):
  File "/opt/homebrew/bin/bpytop", line 3080, in _collect
    if CONFIG.show_cpu_freq and hasattr(psutil.cpu_freq(), "current"):
                                        ^^^^^^^^^^^^^^^^^
  File "/opt/homebrew/Cellar/bpytop/1.0.68/libexec/lib/python3.11/site-packages/psutil/__init__.py", line 1864, in cpu_freq
    ret = _psplatform.cpu_freq()
          ^^^^^^^^^^^^^^^^^^^^^^
  File "/opt/homebrew/Cellar/bpytop/1.0.68/libexec/lib/python3.11/site-packages/psutil/_psosx.py", line 179, in cpu_freq
    curr, min_, max_ = cext.cpu_freq()
                       ^^^^^^^^^^^^^^^
FileNotFoundError: [Errno 2] No such file or directory (originated from sysctl(HW_CPU_FREQ))
30/09/23 (14:33:38) | ERROR: Data collection thread failed with exception: 'io_read'
Traceback (most recent call last):
  File "/opt/homebrew/bin/bpytop", line 2959, in _runner
    collector._draw()
  File "/opt/homebrew/bin/bpytop", line 3991, in _draw
    ProcBox._draw_fg()
  File "/opt/homebrew/bin/bpytop", line 2772, in _draw_fg
    (f'{proc.details["io_read"]:^{iw}.{iw2}}' if expand > 2 else "") + (f'{proc.details["io_write"]:^{iw}.{iw2}}' if expand > 3 else "") +
        ~~~~~~~~~~~~^^^^^^^^^^^
KeyError: 'io_read'
30/09/23 (14:33:38) | WARNING: Exiting with errorcode (1). Runtime 0:37:04 

30/09/23 (20:38:14) | ERROR: Exception while getting cpu frequency!
30/09/23 (20:38:14) | ERROR: [Errno 2] No such file or directory (originated from sysctl(HW_CPU_FREQ))
Traceback (most recent call last):
  File "/opt/homebrew/bin/bpytop", line 3080, in _collect
    if CONFIG.show_cpu_freq and hasattr(psutil.cpu_freq(), "current"):
                                        ^^^^^^^^^^^^^^^^^
  File "/opt/homebrew/Cellar/bpytop/1.0.68/libexec/lib/python3.11/site-packages/psutil/__init__.py", line 1864, in cpu_freq
    ret = _psplatform.cpu_freq()
          ^^^^^^^^^^^^^^^^^^^^^^
  File "/opt/homebrew/Cellar/bpytop/1.0.68/libexec/lib/python3.11/site-packages/psutil/_psosx.py", line 179, in cpu_freq
    curr, min_, max_ = cext.cpu_freq()
                       ^^^^^^^^^^^^^^^
FileNotFoundError: [Errno 2] No such file or directory (originated from sysctl(HW_CPU_FREQ))
01/10/23 (18:43:40) | ERROR: Exception while getting cpu frequency!
01/10/23 (18:43:40) | ERROR: [Errno 2] No such file or directory (originated from sysctl(HW_CPU_FREQ))
Traceback (most recent call last):
  File "/opt/homebrew/bin/bpytop", line 3080, in _collect
    if CONFIG.show_cpu_freq and hasattr(psutil.cpu_freq(), "current"):
                                        ^^^^^^^^^^^^^^^^^
  File "/opt/homebrew/Cellar/bpytop/1.0.68/libexec/lib/python3.11/site-packages/psutil/__init__.py", line 1864, in cpu_freq
    ret = _psplatform.cpu_freq()
          ^^^^^^^^^^^^^^^^^^^^^^
  File "/opt/homebrew/Cellar/bpytop/1.0.68/libexec/lib/python3.11/site-packages/psutil/_psosx.py", line 179, in cpu_freq
    curr, min_, max_ = cext.cpu_freq()
                       ^^^^^^^^^^^^^^^
FileNotFoundError: [Errno 2] No such file or directory (originated from sysctl(HW_CPU_FREQ))
01/10/23 (18:46:41) | ERROR: Exception while getting cpu frequency!
01/10/23 (18:46:41) | ERROR: [Errno 2] No such file or directory (originated from sysctl(HW_CPU_FREQ))
Traceback (most recent call last):
  File "/opt/homebrew/bin/bpytop", line 3080, in _collect
    if CONFIG.show_cpu_freq and hasattr(psutil.cpu_freq(), "current"):
                                        ^^^^^^^^^^^^^^^^^
  File "/opt/homebrew/Cellar/bpytop/1.0.68/libexec/lib/python3.11/site-packages/psutil/__init__.py", line 1864, in cpu_freq
    ret = _psplatform.cpu_freq()
          ^^^^^^^^^^^^^^^^^^^^^^
  File "/opt/homebrew/Cellar/bpytop/1.0.68/libexec/lib/python3.11/site-packages/psutil/_psosx.py", line 179, in cpu_freq
    curr, min_, max_ = cext.cpu_freq()
                       ^^^^^^^^^^^^^^^
FileNotFoundError: [Errno 2] No such file or directory (originated from sysctl(HW_CPU_FREQ))
01/10/23 (18:54:02) | ERROR: Exception while getting cpu frequency!
01/10/23 (18:54:02) | ERROR: [Errno 2] No such file or directory (originated from sysctl(HW_CPU_FREQ))
Traceback (most recent call last):
  File "/opt/homebrew/bin/bpytop", line 3080, in _collect
    if CONFIG.show_cpu_freq and hasattr(psutil.cpu_freq(), "current"):
                                        ^^^^^^^^^^^^^^^^^
  File "/opt/homebrew/Cellar/bpytop/1.0.68/libexec/lib/python3.11/site-packages/psutil/__init__.py", line 1864, in cpu_freq
    ret = _psplatform.cpu_freq()
          ^^^^^^^^^^^^^^^^^^^^^^
  File "/opt/homebrew/Cellar/bpytop/1.0.68/libexec/lib/python3.11/site-packages/psutil/_psosx.py", line 179, in cpu_freq
    curr, min_, max_ = cext.cpu_freq()
                       ^^^^^^^^^^^^^^^
FileNotFoundError: [Errno 2] No such file or directory (originated from sysctl(HW_CPU_FREQ))
01/10/23 (21:26:03) | ERROR: Exception while getting cpu frequency!
01/10/23 (21:26:03) | ERROR: [Errno 2] No such file or directory (originated from sysctl(HW_CPU_FREQ))
Traceback (most recent call last):
  File "/opt/homebrew/bin/bpytop", line 3080, in _collect
    if CONFIG.show_cpu_freq and hasattr(psutil.cpu_freq(), "current"):
                                        ^^^^^^^^^^^^^^^^^
  File "/opt/homebrew/Cellar/bpytop/1.0.68/libexec/lib/python3.11/site-packages/psutil/__init__.py", line 1864, in cpu_freq
    ret = _psplatform.cpu_freq()
          ^^^^^^^^^^^^^^^^^^^^^^
  File "/opt/homebrew/Cellar/bpytop/1.0.68/libexec/lib/python3.11/site-packages/psutil/_psosx.py", line 179, in cpu_freq
    curr, min_, max_ = cext.cpu_freq()
                       ^^^^^^^^^^^^^^^
FileNotFoundError: [Errno 2] No such file or directory (originated from sysctl(HW_CPU_FREQ))
01/10/23 (21:29:01) | ERROR: Exception while getting cpu frequency!
01/10/23 (21:29:01) | ERROR: [Errno 2] No such file or directory (originated from sysctl(HW_CPU_FREQ))
Traceback (most recent call last):
  File "/opt/homebrew/bin/bpytop", line 3080, in _collect
    if CONFIG.show_cpu_freq and hasattr(psutil.cpu_freq(), "current"):
                                        ^^^^^^^^^^^^^^^^^
  File "/opt/homebrew/Cellar/bpytop/1.0.68/libexec/lib/python3.11/site-packages/psutil/__init__.py", line 1864, in cpu_freq
    ret = _psplatform.cpu_freq()
          ^^^^^^^^^^^^^^^^^^^^^^
  File "/opt/homebrew/Cellar/bpytop/1.0.68/libexec/lib/python3.11/site-packages/psutil/_psosx.py", line 179, in cpu_freq
    curr, min_, max_ = cext.cpu_freq()
                       ^^^^^^^^^^^^^^^
FileNotFoundError: [Errno 2] No such file or directory (originated from sysctl(HW_CPU_FREQ))
09/10/23 (17:11:14) | ERROR: Exception while getting cpu frequency!
09/10/23 (17:11:14) | ERROR: [Errno 2] No such file or directory (originated from sysctl(HW_CPU_FREQ))
Traceback (most recent call last):
  File "/opt/homebrew/bin/bpytop", line 3080, in _collect
    if CONFIG.show_cpu_freq and hasattr(psutil.cpu_freq(), "current"):
                                        ^^^^^^^^^^^^^^^^^
  File "/opt/homebrew/Cellar/bpytop/1.0.68/libexec/lib/python3.11/site-packages/psutil/__init__.py", line 1864, in cpu_freq
    ret = _psplatform.cpu_freq()
          ^^^^^^^^^^^^^^^^^^^^^^
  File "/opt/homebrew/Cellar/bpytop/1.0.68/libexec/lib/python3.11/site-packages/psutil/_psosx.py", line 179, in cpu_freq
    curr, min_, max_ = cext.cpu_freq()
                       ^^^^^^^^^^^^^^^
FileNotFoundError: [Errno 2] No such file or directory (originated from sysctl(HW_CPU_FREQ))
09/10/23 (17:18:14) | ERROR: Exception while getting cpu frequency!
09/10/23 (17:18:14) | ERROR: [Errno 2] No such file or directory (originated from sysctl(HW_CPU_FREQ))
Traceback (most recent call last):
  File "/opt/homebrew/bin/bpytop", line 3080, in _collect
    if CONFIG.show_cpu_freq and hasattr(psutil.cpu_freq(), "current"):
                                        ^^^^^^^^^^^^^^^^^
  File "/opt/homebrew/Cellar/bpytop/1.0.68/libexec/lib/python3.11/site-packages/psutil/__init__.py", line 1864, in cpu_freq
    ret = _psplatform.cpu_freq()
          ^^^^^^^^^^^^^^^^^^^^^^
  File "/opt/homebrew/Cellar/bpytop/1.0.68/libexec/lib/python3.11/site-packages/psutil/_psosx.py", line 179, in cpu_freq
    curr, min_, max_ = cext.cpu_freq()
                       ^^^^^^^^^^^^^^^
FileNotFoundError: [Errno 2] No such file or directory (originated from sysctl(HW_CPU_FREQ))
27/10/23 (14:00:33) | ERROR: Exception while getting cpu frequency!
27/10/23 (14:00:33) | ERROR: [Errno 2] No such file or directory (originated from sysctl(HW_CPU_FREQ))
Traceback (most recent call last):
  File "/opt/homebrew/bin/bpytop", line 3080, in _collect
    if CONFIG.show_cpu_freq and hasattr(psutil.cpu_freq(), "current"):
                                        ^^^^^^^^^^^^^^^^^
  File "/opt/homebrew/Cellar/bpytop/1.0.68/libexec/lib/python3.11/site-packages/psutil/__init__.py", line 1864, in cpu_freq
    ret = _psplatform.cpu_freq()
          ^^^^^^^^^^^^^^^^^^^^^^
  File "/opt/homebrew/Cellar/bpytop/1.0.68/libexec/lib/python3.11/site-packages/psutil/_psosx.py", line 179, in cpu_freq
    curr, min_, max_ = cext.cpu_freq()
                       ^^^^^^^^^^^^^^^
FileNotFoundError: [Errno 2] No such file or directory (originated from sysctl(HW_CPU_FREQ))
27/10/23 (14:47:51) | ERROR: Exception while getting cpu frequency!
27/10/23 (14:47:51) | ERROR: [Errno 2] No such file or directory (originated from sysctl(HW_CPU_FREQ))
Traceback (most recent call last):
  File "/opt/homebrew/bin/bpytop", line 3080, in _collect
    if CONFIG.show_cpu_freq and hasattr(psutil.cpu_freq(), "current"):
                                        ^^^^^^^^^^^^^^^^^
  File "/opt/homebrew/Cellar/bpytop/1.0.68/libexec/lib/python3.11/site-packages/psutil/__init__.py", line 1864, in cpu_freq
    ret = _psplatform.cpu_freq()
          ^^^^^^^^^^^^^^^^^^^^^^
  File "/opt/homebrew/Cellar/bpytop/1.0.68/libexec/lib/python3.11/site-packages/psutil/_psosx.py", line 179, in cpu_freq
    curr, min_, max_ = cext.cpu_freq()
                       ^^^^^^^^^^^^^^^
FileNotFoundError: [Errno 2] No such file or directory (originated from sysctl(HW_CPU_FREQ))
20/11/23 (16:19:13) | ERROR: Exception while getting cpu frequency!
20/11/23 (16:19:13) | ERROR: [Errno 2] No such file or directory (originated from sysctl(HW_CPU_FREQ))
Traceback (most recent call last):
  File "/opt/homebrew/bin/bpytop", line 3080, in _collect
    if CONFIG.show_cpu_freq and hasattr(psutil.cpu_freq(), "current"):
                                        ^^^^^^^^^^^^^^^^^
  File "/opt/homebrew/Cellar/bpytop/1.0.68/libexec/lib/python3.11/site-packages/psutil/__init__.py", line 1864, in cpu_freq
    ret = _psplatform.cpu_freq()
          ^^^^^^^^^^^^^^^^^^^^^^
  File "/opt/homebrew/Cellar/bpytop/1.0.68/libexec/lib/python3.11/site-packages/psutil/_psosx.py", line 179, in cpu_freq
    curr, min_, max_ = cext.cpu_freq()
                       ^^^^^^^^^^^^^^^
FileNotFoundError: [Errno 2] No such file or directory (originated from sysctl(HW_CPU_FREQ))
20/11/23 (16:23:16) | ERROR: Exception while getting cpu frequency!
20/11/23 (16:23:16) | ERROR: [Errno 2] No such file or directory (originated from sysctl(HW_CPU_FREQ))
Traceback (most recent call last):
  File "/opt/homebrew/bin/bpytop", line 3080, in _collect
    if CONFIG.show_cpu_freq and hasattr(psutil.cpu_freq(), "current"):
                                        ^^^^^^^^^^^^^^^^^
  File "/opt/homebrew/Cellar/bpytop/1.0.68/libexec/lib/python3.11/site-packages/psutil/__init__.py", line 1864, in cpu_freq
    ret = _psplatform.cpu_freq()
          ^^^^^^^^^^^^^^^^^^^^^^
  File "/opt/homebrew/Cellar/bpytop/1.0.68/libexec/lib/python3.11/site-packages/psutil/_psosx.py", line 179, in cpu_freq
    curr, min_, max_ = cext.cpu_freq()
                       ^^^^^^^^^^^^^^^
FileNotFoundError: [Errno 2] No such file or directory (originated from sysctl(HW_CPU_FREQ))
21/11/23 (12:45:39) | ERROR: Exception while getting cpu frequency!
21/11/23 (12:45:39) | ERROR: [Errno 2] No such file or directory (originated from sysctl(HW_CPU_FREQ))
Traceback (most recent call last):
  File "/opt/homebrew/bin/bpytop", line 3080, in _collect
    if CONFIG.show_cpu_freq and hasattr(psutil.cpu_freq(), "current"):
                                        ^^^^^^^^^^^^^^^^^
  File "/opt/homebrew/Cellar/bpytop/1.0.68/libexec/lib/python3.11/site-packages/psutil/__init__.py", line 1864, in cpu_freq
    ret = _psplatform.cpu_freq()
          ^^^^^^^^^^^^^^^^^^^^^^
  File "/opt/homebrew/Cellar/bpytop/1.0.68/libexec/lib/python3.11/site-packages/psutil/_psosx.py", line 179, in cpu_freq
    curr, min_, max_ = cext.cpu_freq()
                       ^^^^^^^^^^^^^^^
FileNotFoundError: [Errno 2] No such file or directory (originated from sysctl(HW_CPU_FREQ))
21/11/23 (12:46:22) | ERROR: Exception when sending signal 9 to pid 392
21/11/23 (12:46:22) | ERROR: [Errno 1] Operation not permitted
Traceback (most recent call last):
  File "/opt/homebrew/bin/bpytop", line 5479, in process_keys
    os.kill(pid, sig)
PermissionError: [Errno 1] Operation not permitted
22/12/23 (14:32:02) | WARNING: No theme named "+catppuccin_macchiato" found!
22/12/23 (14:32:02) | ERROR: Exception while getting cpu frequency!
22/12/23 (14:32:02) | ERROR: [Errno 2] No such file or directory (originated from sysctl(HW_CPU_FREQ))
Traceback (most recent call last):
  File "/opt/homebrew/bin/bpytop", line 3080, in _collect
    if CONFIG.show_cpu_freq and hasattr(psutil.cpu_freq(), "current"):
                                        ^^^^^^^^^^^^^^^^^
  File "/opt/homebrew/Cellar/bpytop/1.0.68/libexec/lib/python3.11/site-packages/psutil/__init__.py", line 1864, in cpu_freq
    ret = _psplatform.cpu_freq()
          ^^^^^^^^^^^^^^^^^^^^^^
  File "/opt/homebrew/Cellar/bpytop/1.0.68/libexec/lib/python3.11/site-packages/psutil/_psosx.py", line 179, in cpu_freq
    curr, min_, max_ = cext.cpu_freq()
                       ^^^^^^^^^^^^^^^
FileNotFoundError: [Errno 2] No such file or directory (originated from sysctl(HW_CPU_FREQ))
12/01/24 (19:49:42) | ERROR: Exception while getting cpu frequency!
12/01/24 (19:49:42) | ERROR: [Errno 2] No such file or directory (originated from sysctl(HW_CPU_FREQ))
Traceback (most recent call last):
  File "/opt/homebrew/bin/bpytop", line 3080, in _collect
    if CONFIG.show_cpu_freq and hasattr(psutil.cpu_freq(), "current"):
                                        ^^^^^^^^^^^^^^^^^
  File "/opt/homebrew/Cellar/bpytop/1.0.68/libexec/lib/python3.11/site-packages/psutil/__init__.py", line 1864, in cpu_freq
    ret = _psplatform.cpu_freq()
          ^^^^^^^^^^^^^^^^^^^^^^
  File "/opt/homebrew/Cellar/bpytop/1.0.68/libexec/lib/python3.11/site-packages/psutil/_psosx.py", line 179, in cpu_freq
    curr, min_, max_ = cext.cpu_freq()
                       ^^^^^^^^^^^^^^^
FileNotFoundError: [Errno 2] No such file or directory (originated from sysctl(HW_CPU_FREQ))
12/01/24 (19:52:08) | ERROR: Exception while getting cpu frequency!
12/01/24 (19:52:08) | ERROR: [Errno 2] No such file or directory (originated from sysctl(HW_CPU_FREQ))
Traceback (most recent call last):
  File "/opt/homebrew/bin/bpytop", line 3080, in _collect
    if CONFIG.show_cpu_freq and hasattr(psutil.cpu_freq(), "current"):
                                        ^^^^^^^^^^^^^^^^^
  File "/opt/homebrew/Cellar/bpytop/1.0.68/libexec/lib/python3.11/site-packages/psutil/__init__.py", line 1864, in cpu_freq
    ret = _psplatform.cpu_freq()
          ^^^^^^^^^^^^^^^^^^^^^^
  File "/opt/homebrew/Cellar/bpytop/1.0.68/libexec/lib/python3.11/site-packages/psutil/_psosx.py", line 179, in cpu_freq
    curr, min_, max_ = cext.cpu_freq()
                       ^^^^^^^^^^^^^^^
FileNotFoundError: [Errno 2] No such file or directory (originated from sysctl(HW_CPU_FREQ))
15/01/24 (16:05:17) | ERROR: Exception while getting cpu frequency!
15/01/24 (16:05:17) | ERROR: [Errno 2] No such file or directory (originated from sysctl(HW_CPU_FREQ))
Traceback (most recent call last):
  File "/opt/homebrew/bin/bpytop", line 3080, in _collect
    if CONFIG.show_cpu_freq and hasattr(psutil.cpu_freq(), "current"):
                                        ^^^^^^^^^^^^^^^^^
  File "/opt/homebrew/Cellar/bpytop/1.0.68/libexec/lib/python3.11/site-packages/psutil/__init__.py", line 1864, in cpu_freq
    ret = _psplatform.cpu_freq()
          ^^^^^^^^^^^^^^^^^^^^^^
  File "/opt/homebrew/Cellar/bpytop/1.0.68/libexec/lib/python3.11/site-packages/psutil/_psosx.py", line 179, in cpu_freq
    curr, min_, max_ = cext.cpu_freq()
                       ^^^^^^^^^^^^^^^
FileNotFoundError: [Errno 2] No such file or directory (originated from sysctl(HW_CPU_FREQ))
17/01/24 (17:26:09) | ERROR: Exception while getting cpu frequency!
17/01/24 (17:26:09) | ERROR: [Errno 2] No such file or directory (originated from sysctl(HW_CPU_FREQ))
Traceback (most recent call last):
  File "/opt/homebrew/bin/bpytop", line 3080, in _collect
    if CONFIG.show_cpu_freq and hasattr(psutil.cpu_freq(), "current"):
                                        ^^^^^^^^^^^^^^^^^
  File "/opt/homebrew/Cellar/bpytop/1.0.68/libexec/lib/python3.11/site-packages/psutil/__init__.py", line 1864, in cpu_freq
    ret = _psplatform.cpu_freq()
          ^^^^^^^^^^^^^^^^^^^^^^
  File "/opt/homebrew/Cellar/bpytop/1.0.68/libexec/lib/python3.11/site-packages/psutil/_psosx.py", line 179, in cpu_freq
    curr, min_, max_ = cext.cpu_freq()
                       ^^^^^^^^^^^^^^^
FileNotFoundError: [Errno 2] No such file or directory (originated from sysctl(HW_CPU_FREQ))
17/01/24 (17:27:39) | ERROR: Exception while getting cpu frequency!
17/01/24 (17:27:39) | ERROR: [Errno 2] No such file or directory (originated from sysctl(HW_CPU_FREQ))
Traceback (most recent call last):
  File "/opt/homebrew/bin/bpytop", line 3080, in _collect
    if CONFIG.show_cpu_freq and hasattr(psutil.cpu_freq(), "current"):
                                        ^^^^^^^^^^^^^^^^^
  File "/opt/homebrew/Cellar/bpytop/1.0.68/libexec/lib/python3.11/site-packages/psutil/__init__.py", line 1864, in cpu_freq
    ret = _psplatform.cpu_freq()
          ^^^^^^^^^^^^^^^^^^^^^^
  File "/opt/homebrew/Cellar/bpytop/1.0.68/libexec/lib/python3.11/site-packages/psutil/_psosx.py", line 179, in cpu_freq
    curr, min_, max_ = cext.cpu_freq()
                       ^^^^^^^^^^^^^^^
FileNotFoundError: [Errno 2] No such file or directory (originated from sysctl(HW_CPU_FREQ))
18/01/24 (17:20:52) | ERROR: Exception while getting cpu frequency!
18/01/24 (17:20:52) | ERROR: [Errno 2] No such file or directory (originated from sysctl(HW_CPU_FREQ))
Traceback (most recent call last):
  File "/opt/homebrew/bin/bpytop", line 3080, in _collect
    if CONFIG.show_cpu_freq and hasattr(psutil.cpu_freq(), "current"):
                                        ^^^^^^^^^^^^^^^^^
  File "/opt/homebrew/Cellar/bpytop/1.0.68/libexec/lib/python3.11/site-packages/psutil/__init__.py", line 1864, in cpu_freq
    ret = _psplatform.cpu_freq()
          ^^^^^^^^^^^^^^^^^^^^^^
  File "/opt/homebrew/Cellar/bpytop/1.0.68/libexec/lib/python3.11/site-packages/psutil/_psosx.py", line 179, in cpu_freq
    curr, min_, max_ = cext.cpu_freq()
                       ^^^^^^^^^^^^^^^
FileNotFoundError: [Errno 2] No such file or directory (originated from sysctl(HW_CPU_FREQ))
18/01/24 (17:21:24) | ERROR: Exception while getting cpu frequency!
18/01/24 (17:21:24) | ERROR: [Errno 2] No such file or directory (originated from sysctl(HW_CPU_FREQ))
Traceback (most recent call last):
  File "/opt/homebrew/bin/bpytop", line 3080, in _collect
    if CONFIG.show_cpu_freq and hasattr(psutil.cpu_freq(), "current"):
                                        ^^^^^^^^^^^^^^^^^
  File "/opt/homebrew/Cellar/bpytop/1.0.68/libexec/lib/python3.11/site-packages/psutil/__init__.py", line 1864, in cpu_freq
    ret = _psplatform.cpu_freq()
          ^^^^^^^^^^^^^^^^^^^^^^
  File "/opt/homebrew/Cellar/bpytop/1.0.68/libexec/lib/python3.11/site-packages/psutil/_psosx.py", line 179, in cpu_freq
    curr, min_, max_ = cext.cpu_freq()
                       ^^^^^^^^^^^^^^^
FileNotFoundError: [Errno 2] No such file or directory (originated from sysctl(HW_CPU_FREQ))
18/01/24 (17:23:09) | ERROR: Exception while getting cpu frequency!
18/01/24 (17:23:09) | ERROR: [Errno 2] No such file or directory (originated from sysctl(HW_CPU_FREQ))
Traceback (most recent call last):
  File "/opt/homebrew/bin/bpytop", line 3080, in _collect
    if CONFIG.show_cpu_freq and hasattr(psutil.cpu_freq(), "current"):
                                        ^^^^^^^^^^^^^^^^^
  File "/opt/homebrew/Cellar/bpytop/1.0.68/libexec/lib/python3.11/site-packages/psutil/__init__.py", line 1864, in cpu_freq
    ret = _psplatform.cpu_freq()
          ^^^^^^^^^^^^^^^^^^^^^^
  File "/opt/homebrew/Cellar/bpytop/1.0.68/libexec/lib/python3.11/site-packages/psutil/_psosx.py", line 179, in cpu_freq
    curr, min_, max_ = cext.cpu_freq()
                       ^^^^^^^^^^^^^^^
FileNotFoundError: [Errno 2] No such file or directory (originated from sysctl(HW_CPU_FREQ))
18/01/24 (17:26:39) | ERROR: Exception while getting cpu frequency!
18/01/24 (17:26:39) | ERROR: [Errno 2] No such file or directory (originated from sysctl(HW_CPU_FREQ))
Traceback (most recent call last):
  File "/opt/homebrew/bin/bpytop", line 3080, in _collect
    if CONFIG.show_cpu_freq and hasattr(psutil.cpu_freq(), "current"):
                                        ^^^^^^^^^^^^^^^^^
  File "/opt/homebrew/Cellar/bpytop/1.0.68/libexec/lib/python3.11/site-packages/psutil/__init__.py", line 1864, in cpu_freq
    ret = _psplatform.cpu_freq()
          ^^^^^^^^^^^^^^^^^^^^^^
  File "/opt/homebrew/Cellar/bpytop/1.0.68/libexec/lib/python3.11/site-packages/psutil/_psosx.py", line 179, in cpu_freq
    curr, min_, max_ = cext.cpu_freq()
                       ^^^^^^^^^^^^^^^
FileNotFoundError: [Errno 2] No such file or directory (originated from sysctl(HW_CPU_FREQ))
19/01/24 (23:19:04) | ERROR: Exception while getting cpu frequency!
19/01/24 (23:19:04) | ERROR: [Errno 2] No such file or directory (originated from sysctl(HW_CPU_FREQ))
Traceback (most recent call last):
  File "/opt/homebrew/bin/bpytop", line 3080, in _collect
    if CONFIG.show_cpu_freq and hasattr(psutil.cpu_freq(), "current"):
                                        ^^^^^^^^^^^^^^^^^
  File "/opt/homebrew/Cellar/bpytop/1.0.68/libexec/lib/python3.11/site-packages/psutil/__init__.py", line 1864, in cpu_freq
    ret = _psplatform.cpu_freq()
          ^^^^^^^^^^^^^^^^^^^^^^
  File "/opt/homebrew/Cellar/bpytop/1.0.68/libexec/lib/python3.11/site-packages/psutil/_psosx.py", line 179, in cpu_freq
    curr, min_, max_ = cext.cpu_freq()
                       ^^^^^^^^^^^^^^^
FileNotFoundError: [Errno 2] No such file or directory (originated from sysctl(HW_CPU_FREQ))
19/01/24 (23:22:50) | ERROR: Exception while getting cpu frequency!
19/01/24 (23:22:50) | ERROR: [Errno 2] No such file or directory (originated from sysctl(HW_CPU_FREQ))
Traceback (most recent call last):
  File "/opt/homebrew/bin/bpytop", line 3080, in _collect
    if CONFIG.show_cpu_freq and hasattr(psutil.cpu_freq(), "current"):
                                        ^^^^^^^^^^^^^^^^^
  File "/opt/homebrew/Cellar/bpytop/1.0.68/libexec/lib/python3.11/site-packages/psutil/__init__.py", line 1864, in cpu_freq
    ret = _psplatform.cpu_freq()
          ^^^^^^^^^^^^^^^^^^^^^^
  File "/opt/homebrew/Cellar/bpytop/1.0.68/libexec/lib/python3.11/site-packages/psutil/_psosx.py", line 179, in cpu_freq
    curr, min_, max_ = cext.cpu_freq()
                       ^^^^^^^^^^^^^^^
FileNotFoundError: [Errno 2] No such file or directory (originated from sysctl(HW_CPU_FREQ))
19/01/24 (23:25:07) | ERROR: Exception while getting cpu frequency!
19/01/24 (23:25:07) | ERROR: [Errno 2] No such file or directory (originated from sysctl(HW_CPU_FREQ))
Traceback (most recent call last):
  File "/opt/homebrew/bin/bpytop", line 3080, in _collect
    if CONFIG.show_cpu_freq and hasattr(psutil.cpu_freq(), "current"):
                                        ^^^^^^^^^^^^^^^^^
  File "/opt/homebrew/Cellar/bpytop/1.0.68/libexec/lib/python3.11/site-packages/psutil/__init__.py", line 1864, in cpu_freq
    ret = _psplatform.cpu_freq()
          ^^^^^^^^^^^^^^^^^^^^^^
  File "/opt/homebrew/Cellar/bpytop/1.0.68/libexec/lib/python3.11/site-packages/psutil/_psosx.py", line 179, in cpu_freq
    curr, min_, max_ = cext.cpu_freq()
                       ^^^^^^^^^^^^^^^
FileNotFoundError: [Errno 2] No such file or directory (originated from sysctl(HW_CPU_FREQ))
19/01/24 (23:45:06) | ERROR: Exception while getting cpu frequency!
19/01/24 (23:45:06) | ERROR: [Errno 2] No such file or directory (originated from sysctl(HW_CPU_FREQ))
Traceback (most recent call last):
  File "/opt/homebrew/bin/bpytop", line 3080, in _collect
    if CONFIG.show_cpu_freq and hasattr(psutil.cpu_freq(), "current"):
                                        ^^^^^^^^^^^^^^^^^
  File "/opt/homebrew/Cellar/bpytop/1.0.68/libexec/lib/python3.11/site-packages/psutil/__init__.py", line 1864, in cpu_freq
    ret = _psplatform.cpu_freq()
          ^^^^^^^^^^^^^^^^^^^^^^
  File "/opt/homebrew/Cellar/bpytop/1.0.68/libexec/lib/python3.11/site-packages/psutil/_psosx.py", line 179, in cpu_freq
    curr, min_, max_ = cext.cpu_freq()
                       ^^^^^^^^^^^^^^^
FileNotFoundError: [Errno 2] No such file or directory (originated from sysctl(HW_CPU_FREQ))
23/01/24 (10:57:29) | ERROR: Exception while getting cpu frequency!
23/01/24 (10:57:29) | ERROR: [Errno 2] No such file or directory (originated from sysctl(HW_CPU_FREQ))
Traceback (most recent call last):
  File "/opt/homebrew/bin/bpytop", line 3080, in _collect
    if CONFIG.show_cpu_freq and hasattr(psutil.cpu_freq(), "current"):
                                        ^^^^^^^^^^^^^^^^^
  File "/opt/homebrew/Cellar/bpytop/1.0.68/libexec/lib/python3.11/site-packages/psutil/__init__.py", line 1864, in cpu_freq
    ret = _psplatform.cpu_freq()
          ^^^^^^^^^^^^^^^^^^^^^^
  File "/opt/homebrew/Cellar/bpytop/1.0.68/libexec/lib/python3.11/site-packages/psutil/_psosx.py", line 179, in cpu_freq
    curr, min_, max_ = cext.cpu_freq()
                       ^^^^^^^^^^^^^^^
FileNotFoundError: [Errno 2] No such file or directory (originated from sysctl(HW_CPU_FREQ))
23/01/24 (10:58:40) | ERROR: Exception while getting cpu frequency!
23/01/24 (10:58:40) | ERROR: [Errno 2] No such file or directory (originated from sysctl(HW_CPU_FREQ))
Traceback (most recent call last):
  File "/opt/homebrew/bin/bpytop", line 3080, in _collect
    if CONFIG.show_cpu_freq and hasattr(psutil.cpu_freq(), "current"):
                                        ^^^^^^^^^^^^^^^^^
  File "/opt/homebrew/Cellar/bpytop/1.0.68/libexec/lib/python3.11/site-packages/psutil/__init__.py", line 1864, in cpu_freq
    ret = _psplatform.cpu_freq()
          ^^^^^^^^^^^^^^^^^^^^^^
  File "/opt/homebrew/Cellar/bpytop/1.0.68/libexec/lib/python3.11/site-packages/psutil/_psosx.py", line 179, in cpu_freq
    curr, min_, max_ = cext.cpu_freq()
                       ^^^^^^^^^^^^^^^
FileNotFoundError: [Errno 2] No such file or directory (originated from sysctl(HW_CPU_FREQ))
27/01/24 (17:09:56) | ERROR: Exception while getting cpu frequency!
27/01/24 (17:09:56) | ERROR: [Errno 2] No such file or directory (originated from sysctl(HW_CPU_FREQ))
Traceback (most recent call last):
  File "/opt/homebrew/bin/bpytop", line 3080, in _collect
    if CONFIG.show_cpu_freq and hasattr(psutil.cpu_freq(), "current"):
                                        ^^^^^^^^^^^^^^^^^
  File "/opt/homebrew/Cellar/bpytop/1.0.68/libexec/lib/python3.11/site-packages/psutil/__init__.py", line 1864, in cpu_freq
    ret = _psplatform.cpu_freq()
          ^^^^^^^^^^^^^^^^^^^^^^
  File "/opt/homebrew/Cellar/bpytop/1.0.68/libexec/lib/python3.11/site-packages/psutil/_psosx.py", line 179, in cpu_freq
    curr, min_, max_ = cext.cpu_freq()
                       ^^^^^^^^^^^^^^^
FileNotFoundError: [Errno 2] No such file or directory (originated from sysctl(HW_CPU_FREQ))
27/01/24 (17:18:55) | ERROR: Exception while getting cpu frequency!
27/01/24 (17:18:55) | ERROR: [Errno 2] No such file or directory (originated from sysctl(HW_CPU_FREQ))
Traceback (most recent call last):
  File "/opt/homebrew/bin/bpytop", line 3080, in _collect
    if CONFIG.show_cpu_freq and hasattr(psutil.cpu_freq(), "current"):
                                        ^^^^^^^^^^^^^^^^^
  File "/opt/homebrew/Cellar/bpytop/1.0.68/libexec/lib/python3.11/site-packages/psutil/__init__.py", line 1864, in cpu_freq
    ret = _psplatform.cpu_freq()
          ^^^^^^^^^^^^^^^^^^^^^^
  File "/opt/homebrew/Cellar/bpytop/1.0.68/libexec/lib/python3.11/site-packages/psutil/_psosx.py", line 179, in cpu_freq
    curr, min_, max_ = cext.cpu_freq()
                       ^^^^^^^^^^^^^^^
FileNotFoundError: [Errno 2] No such file or directory (originated from sysctl(HW_CPU_FREQ))
09/02/24 (11:53:06) | ERROR: Exception while getting cpu frequency!
09/02/24 (11:53:06) | ERROR: [Errno 2] No such file or directory (originated from sysctl(HW_CPU_FREQ))
Traceback (most recent call last):
  File "/opt/homebrew/bin/bpytop", line 3080, in _collect
    if CONFIG.show_cpu_freq and hasattr(psutil.cpu_freq(), "current"):
                                        ^^^^^^^^^^^^^^^^^
  File "/opt/homebrew/Cellar/bpytop/1.0.68/libexec/lib/python3.11/site-packages/psutil/__init__.py", line 1864, in cpu_freq
    ret = _psplatform.cpu_freq()
          ^^^^^^^^^^^^^^^^^^^^^^
  File "/opt/homebrew/Cellar/bpytop/1.0.68/libexec/lib/python3.11/site-packages/psutil/_psosx.py", line 179, in cpu_freq
    curr, min_, max_ = cext.cpu_freq()
                       ^^^^^^^^^^^^^^^
FileNotFoundError: [Errno 2] No such file or directory (originated from sysctl(HW_CPU_FREQ))
15/02/24 (17:21:38) | ERROR: Exception while getting cpu frequency!
15/02/24 (17:21:38) | ERROR: [Errno 2] No such file or directory (originated from sysctl(HW_CPU_FREQ))
Traceback (most recent call last):
  File "/opt/homebrew/bin/bpytop", line 3080, in _collect
    if CONFIG.show_cpu_freq and hasattr(psutil.cpu_freq(), "current"):
                                        ^^^^^^^^^^^^^^^^^
  File "/opt/homebrew/Cellar/bpytop/1.0.68/libexec/lib/python3.11/site-packages/psutil/__init__.py", line 1864, in cpu_freq
    ret = _psplatform.cpu_freq()
          ^^^^^^^^^^^^^^^^^^^^^^
  File "/opt/homebrew/Cellar/bpytop/1.0.68/libexec/lib/python3.11/site-packages/psutil/_psosx.py", line 179, in cpu_freq
    curr, min_, max_ = cext.cpu_freq()
                       ^^^^^^^^^^^^^^^
FileNotFoundError: [Errno 2] No such file or directory (originated from sysctl(HW_CPU_FREQ))
21/02/24 (18:39:40) | ERROR: Exception while getting cpu frequency!
21/02/24 (18:39:40) | ERROR: [Errno 2] No such file or directory (originated from sysctl(HW_CPU_FREQ))
Traceback (most recent call last):
  File "/opt/homebrew/bin/bpytop", line 3080, in _collect
    if CONFIG.show_cpu_freq and hasattr(psutil.cpu_freq(), "current"):
                                        ^^^^^^^^^^^^^^^^^
  File "/opt/homebrew/Cellar/bpytop/1.0.68/libexec/lib/python3.11/site-packages/psutil/__init__.py", line 1864, in cpu_freq
    ret = _psplatform.cpu_freq()
          ^^^^^^^^^^^^^^^^^^^^^^
  File "/opt/homebrew/Cellar/bpytop/1.0.68/libexec/lib/python3.11/site-packages/psutil/_psosx.py", line 179, in cpu_freq
    curr, min_, max_ = cext.cpu_freq()
                       ^^^^^^^^^^^^^^^
FileNotFoundError: [Errno 2] No such file or directory (originated from sysctl(HW_CPU_FREQ))
18/03/24 (12:25:27) | ERROR: Exception while getting cpu frequency!
18/03/24 (12:25:27) | ERROR: [Errno 2] No such file or directory (originated from sysctl(HW_CPU_FREQ))
Traceback (most recent call last):
  File "/opt/homebrew/bin/bpytop", line 3080, in _collect
    if CONFIG.show_cpu_freq and hasattr(psutil.cpu_freq(), "current"):
                                        ^^^^^^^^^^^^^^^^^
  File "/opt/homebrew/Cellar/bpytop/1.0.68/libexec/lib/python3.11/site-packages/psutil/__init__.py", line 1864, in cpu_freq
    ret = _psplatform.cpu_freq()
          ^^^^^^^^^^^^^^^^^^^^^^
  File "/opt/homebrew/Cellar/bpytop/1.0.68/libexec/lib/python3.11/site-packages/psutil/_psosx.py", line 179, in cpu_freq
    curr, min_, max_ = cext.cpu_freq()
                       ^^^^^^^^^^^^^^^
FileNotFoundError: [Errno 2] No such file or directory (originated from sysctl(HW_CPU_FREQ))
18/03/24 (12:25:58) | ERROR: Exception while getting cpu frequency!
18/03/24 (12:25:58) | ERROR: [Errno 2] No such file or directory (originated from sysctl(HW_CPU_FREQ))
Traceback (most recent call last):
  File "/opt/homebrew/bin/bpytop", line 3080, in _collect
    if CONFIG.show_cpu_freq and hasattr(psutil.cpu_freq(), "current"):
                                        ^^^^^^^^^^^^^^^^^
  File "/opt/homebrew/Cellar/bpytop/1.0.68/libexec/lib/python3.11/site-packages/psutil/__init__.py", line 1864, in cpu_freq
    ret = _psplatform.cpu_freq()
          ^^^^^^^^^^^^^^^^^^^^^^
  File "/opt/homebrew/Cellar/bpytop/1.0.68/libexec/lib/python3.11/site-packages/psutil/_psosx.py", line 179, in cpu_freq
    curr, min_, max_ = cext.cpu_freq()
                       ^^^^^^^^^^^^^^^
FileNotFoundError: [Errno 2] No such file or directory (originated from sysctl(HW_CPU_FREQ))
18/03/24 (17:14:28) | ERROR: Exception while getting cpu frequency!
18/03/24 (17:14:28) | ERROR: [Errno 2] No such file or directory (originated from sysctl(HW_CPU_FREQ))
Traceback (most recent call last):
  File "/opt/homebrew/bin/bpytop", line 3080, in _collect
    if CONFIG.show_cpu_freq and hasattr(psutil.cpu_freq(), "current"):
                                        ^^^^^^^^^^^^^^^^^
  File "/opt/homebrew/Cellar/bpytop/1.0.68/libexec/lib/python3.11/site-packages/psutil/__init__.py", line 1864, in cpu_freq
    ret = _psplatform.cpu_freq()
          ^^^^^^^^^^^^^^^^^^^^^^
  File "/opt/homebrew/Cellar/bpytop/1.0.68/libexec/lib/python3.11/site-packages/psutil/_psosx.py", line 179, in cpu_freq
    curr, min_, max_ = cext.cpu_freq()
                       ^^^^^^^^^^^^^^^
FileNotFoundError: [Errno 2] No such file or directory (originated from sysctl(HW_CPU_FREQ))
28/07/24 (22:25:09) | ERROR: Exception while getting cpu frequency!
28/07/24 (22:25:09) | ERROR: [Errno 2] No such file or directory (originated from sysctl(HW_CPU_FREQ))
Traceback (most recent call last):
  File "/opt/homebrew/bin/bpytop", line 3080, in _collect
    if CONFIG.show_cpu_freq and hasattr(psutil.cpu_freq(), "current"):
                                        ^^^^^^^^^^^^^^^^^
  File "/opt/homebrew/Cellar/bpytop/1.0.68/libexec/lib/python3.11/site-packages/psutil/__init__.py", line 1864, in cpu_freq
    ret = _psplatform.cpu_freq()
          ^^^^^^^^^^^^^^^^^^^^^^
  File "/opt/homebrew/Cellar/bpytop/1.0.68/libexec/lib/python3.11/site-packages/psutil/_psosx.py", line 179, in cpu_freq
    curr, min_, max_ = cext.cpu_freq()
                       ^^^^^^^^^^^^^^^
FileNotFoundError: [Errno 2] No such file or directory (originated from sysctl(HW_CPU_FREQ))
